Workbook

Sheet 01_手动输入
A1: CATL 四层映射引擎 通用模板 - 手动输入总表
A2: 说明：只有本 Sheet 允许手动修改。黄色列是实际输入值，模板默认填入通用示例值，后面所有 Sheet 都由公式自动拉取与计算。
A3: 类别 | B3: 字段代码 | C3: 手动输入项（中文） | D3: 英文对应 | E3: 单位 | F3: 示例值 | G3: 实际输入值 | H3: 说明 | I3: 常见证据 | J3: 主要影响输出 | K3: 字段数据类型 | L3: 是否必填 | M3: 录入方式 | N3: 建议来源系统 | O3: 字段责任人 | P3: 保密等级 | Q3: 校验规则ID | R3: 缺口状态 | S3: 可直接复用CATL公开披露? | T3: 下一步动作
A4: A. 基本身份 | B4: manufacturer_name | C4: 制造商名称 | D4: manufacturer name | E4: 文本 | F4: CATL | G4: CATL | H4: 公司主体识别字段 | I4: 营业执照/年报 | J4: EU+CBAM | K4: =IFERROR(INDEX('12_字段字典'!$D:$D,MATCH($B4,'12_字段字典'!$B:$B,0)),"") | L4: =IFERROR(INDEX('12_字段字典'!$E:$E,MATCH($B4,'12_字段字典'!$B:$B,0)),"") | M4: =IFERROR(INDEX('12_字段字典'!$F:$F,MATCH($B4,'12_字段字典'!$B:$B,0)),"") | N4: =IFERROR(INDEX('12_字段字典'!$G:$G,MATCH($B4,'12_字段字典'!$B:$B,0)),"") | O4: =IFERROR(INDEX('12_字段字典'!$H:$H,MATCH($B4,'12_字段字典'!$B:$B,0)),"") | P4: =IFERROR(INDEX('12_字段字典'!$I:$I,MATCH($B4,'12_字段字典'!$B:$B,0)),"") | Q4: =IFERROR(INDEX('12_字段字典'!$J:$J,MATCH($B4,'12_字段字典'!$B:$B,0)),"") | R4: =IFERROR(INDEX('12_字段字典'!$K:$K,MATCH($B4,'12_字段字典'!$B:$B,0)),"") | S4: =IFERROR(INDEX('12_字段字典'!$L:$L,MATCH($B4,'12_字段字典'!$B:$B,0)),"") | T4: =IFERROR(INDEX('12_字段字典'!$M:$M,MATCH($B4,'12_字段字典'!$B:$B,0)),"")
A5: A. 基本身份 | B5: product_name | C5: 产品名称 | D5: product name | E5: 文本 | F5: CATL 通用电池产品模板（Generic Example） | G5: CATL 通用电池产品模板（Generic Example） | H5: 用于任意 CATL 电池产品的模板名称，而非固定神行案例 | I5: 产品主数据 | J5: EU | K5: =IFERROR(INDEX('12_字段字典'!$D:$D,MATCH($B5,'12_字段字典'!$B:$B,0)),"") | L5: =IFERROR(INDEX('12_字段字典'!$E:$E,MATCH($B5,'12_字段字典'!$B:$B,0)),"") | M5: =IFERROR(INDEX('12_字段字典'!$F:$F,MATCH($B5,'12_字段字典'!$B:$B,0)),"") | N5: =IFERROR(INDEX('12_字段字典'!$G:$G,MATCH($B5,'12_字段字典'!$B:$B,0)),"") | O5: =IFERROR(INDEX('12_字段字典'!$H:$H,MATCH($B5,'12_字段字典'!$B:$B,0)),"") | P5: =IFERROR(INDEX('12_字段字典'!$I:$I,MATCH($B5,'12_字段字典'!$B:$B,0)),"") | Q5: =IFERROR(INDEX('12_字段字典'!$J:$J,MATCH($B5,'12_字段字典'!$B:$B,0)),"") | R5: =IFERROR(INDEX('12_字段字典'!$K:$K,MATCH($B5,'12_字段字典'!$B:$B,0)),"") | S5: =IFERROR(INDEX('12_字段字典'!$L:$L,MATCH($B5,'12_字段字典'!$B:$B,0)),"") | T5: =IFERROR(INDEX('12_字段字典'!$M:$M,MATCH($B5,'12_字段字典'!$B:$B,0)),"")
A6: A. 基本身份 | B6: model_code | C6: 电池型号代码 | D6: battery model identifier | E6: 文本 | F6: GENERIC-BATTERY-MODEL-001 | G6: GENERIC-BATTERY-MODEL-001 | H6: 通用模板的产品锚点，可替换为任意实际型号 | I6: 型号注册表 | J6: EU+CBAM | K6: =IFERROR(INDEX('12_字段字典'!$D:$D,MATCH($B6,'12_字段字典'!$B:$B,0)),"") | L6: =IFERROR(INDEX('12_字段字典'!$E:$E,MATCH($B6,'12_字段字典'!$B:$B,0)),"") | M6: =IFERROR(INDEX('12_字段字典'!$F:$F,MATCH($B6,'12_字段字典'!$B:$B,0)),"") | N6: =IFERROR(INDEX('12_字段字典'!$G:$G,MATCH($B6,'12_字段字典'!$B:$B,0)),"") | O6: =IFERROR(INDEX('12_字段字典'!$H:$H,MATCH($B6,'12_字段字典'!$B:$B,0)),"") | P6: =IFERROR(INDEX('12_字段字典'!$I:$I,MATCH($B6,'12_字段字典'!$B:$B,0)),"") | Q6: =IFERROR(INDEX('12_字段字典'!$J:$J,MATCH($B6,'12_字段字典'!$B:$B,0)),"") | R6: =IFERROR(INDEX('12_字段字典'!$K:$K,MATCH($B6,'12_字段字典'!$B:$B,0)),"") | S6: =IFERROR(INDEX('12_字段字典'!$L:$L,MATCH($B6,'12_字段字典'!$B:$B,0)),"") | T6: =IFERROR(INDEX('12_字段字典'!$M:$M,MATCH($B6,'12_字段字典'!$B:$B,0)),"")
A7: A. 基本身份 | B7: battery_category | C7: 产品业务类别 | D7: product business category | E7: 文本 | F7: EV battery / ESS battery / special application | G7: EV battery / ESS battery / special application | H7: 这是业务和产品线分类；正式欧盟监管适用类别请看 regulatory_battery_class | I7: 技术规格书 | J7: EU | K7: =IFERROR(INDEX('12_字段字典'!$D:$D,MATCH($B7,'12_字段字典'!$B:$B,0)),"") | L7: =IFERROR(INDEX('12_字段字典'!$E:$E,MATCH($B7,'12_字段字典'!$B:$B,0)),"") | M7: =IFERROR(INDEX('12_字段字典'!$F:$F,MATCH($B7,'12_字段字典'!$B:$B,0)),"") | N7: =IFERROR(INDEX('12_字段字典'!$G:$G,MATCH($B7,'12_字段字典'!$B:$B,0)),"") | O7: =IFERROR(INDEX('12_字段字典'!$H:$H,MATCH($B7,'12_字段字典'!$B:$B,0)),"") | P7: =IFERROR(INDEX('12_字段字典'!$I:$I,MATCH($B7,'12_字段字典'!$B:$B,0)),"") | Q7: =IFERROR(INDEX('12_字段字典'!$J:$J,MATCH($B7,'12_字段字典'!$B:$B,0)),"") | R7: =IFERROR(INDEX('12_字段字典'!$K:$K,MATCH($B7,'12_字段字典'!$B:$B,0)),"") | S7: =IFERROR(INDEX('12_字段字典'!$L:$L,MATCH($B7,'12_字段字典'!$B:$B,0)),"") | T7: =IFERROR(INDEX('12_字段字典'!$M:$M,MATCH($B7,'12_字段字典'!$B:$B,0)),"")
A8: A. 基本身份 | B8: chemistry | C8: 化学体系 | D8: chemistry | E8: 文本 | F8: LFP / LMFP / NMC（模板示例） | G8: LFP / LMFP / NMC（模板示例） | H8: 保留化学体系接口，但不绑定单一神行配方 | I8: BOM/规格书 | J8: EU+CBAM | K8: =IFERROR(INDEX('12_字段字典'!$D:$D,MATCH($B8,'12_字段字典'!$B:$B,0)),"") | L8: =IFERROR(INDEX('12_字段字典'!$E:$E,MATCH($B8,'12_字段字典'!$B:$B,0)),"") | M8: =IFERROR(INDEX('12_字段字典'!$F:$F,MATCH($B8,'12_字段字典'!$B:$B,0)),"") | N8: =IFERROR(INDEX('12_字段字典'!$G:$G,MATCH($B8,'12_字段字典'!$B:$B,0)),"") | O8: =IFERROR(INDEX('12_字段字典'!$H:$H,MATCH($B8,'12_字段字典'!$B:$B,0)),"") | P8: =IFERROR(INDEX('12_字段字典'!$I:$I,MATCH($B8,'12_字段字典'!$B:$B,0)),"") | Q8: =IFERROR(INDEX('12_字段字典'!$J:$J,MATCH($B8,'12_字段字典'!$B:$B,0)),"") | R8: =IFERROR(INDEX('12_字段字典'!$K:$K,MATCH($B8,'12_字段字典'!$B:$B,0)),"") | S8: =IFERROR(INDEX('12_字段字典'!$L:$L,MATCH($B8,'12_字段字典'!$B:$B,0)),"") | T8: =IFERROR(INDEX('12_字段字典'!$M:$M,MATCH($B8,'12_字段字典'!$B:$B,0)),"")
A9: A. 基本身份 | B9: plant_code | C9: 制造工厂代码 | D9: plant code | E9: 文本 | F9: CN-PLANT-TEMPLATE-001 | G9: CN-PLANT-TEMPLATE-001 | H9: 主要制造工厂代码；若产品还涉及单独总成装配地点，请同时填写 assembly_site_* 字段 | I9: 工厂注册表 | J9: EU+CBAM | K9: =IFERROR(INDEX('12_字段字典'!$D:$D,MATCH($B9,'12_字段字典'!$B:$B,0)),"") | L9: =IFERROR(INDEX('12_字段字典'!$E:$E,MATCH($B9,'12_字段字典'!$B:$B,0)),"") | M9: =IFERROR(INDEX('12_字段字典'!$F:$F,MATCH($B9,'12_字段字典'!$B:$B,0)),"") | N9: =IFERROR(INDEX('12_字段字典'!$G:$G,MATCH($B9,'12_字段字典'!$B:$B,0)),"") | O9: =IFERROR(INDEX('12_字段字典'!$H:$H,MATCH($B9,'12_字段字典'!$B:$B,0)),"") | P9: =IFERROR(INDEX('12_字段字典'!$I:$I,MATCH($B9,'12_字段字典'!$B:$B,0)),"") | Q9: =IFERROR(INDEX('12_字段字典'!$J:$J,MATCH($B9,'12_字段字典'!$B:$B,0)),"") | R9: =IFERROR(INDEX('12_字段字典'!$K:$K,MATCH($B9,'12_字段字典'!$B:$B,0)),"") | S9: =IFERROR(INDEX('12_字段字典'!$L:$L,MATCH($B9,'12_字段字典'!$B:$B,0)),"") | T9: =IFERROR(INDEX('12_字段字典'!$M:$M,MATCH($B9,'12_字段字典'!$B:$B,0)),"")
A10: A. 基本身份 | B10: plant_name | C10: 制造工厂名称 | D10: plant name | E10: 文本 | F10: 某制造工厂（模板） | G10: 某制造工厂（模板） | H10: 主要制造工厂名称；用于绑定主申报工厂 | I10: 工厂主数据 | J10: EU | K10: =IFERROR(INDEX('12_字段字典'!$D:$D,MATCH($B10,'12_字段字典'!$B:$B,0)),"") | L10: =IFERROR(INDEX('12_字段字典'!$E:$E,MATCH($B10,'12_字段字典'!$B:$B,0)),"") | M10: =IFERROR(INDEX('12_字段字典'!$F:$F,MATCH($B10,'12_字段字典'!$B:$B,0)),"") | N10: =IFERROR(INDEX('12_字段字典'!$G:$G,MATCH($B10,'12_字段字典'!$B:$B,0)),"") | O10: =IFERROR(INDEX('12_字段字典'!$H:$H,MATCH($B10,'12_字段字典'!$B:$B,0)),"") | P10: =IFERROR(INDEX('12_字段字典'!$I:$I,MATCH($B10,'12_字段字典'!$B:$B,0)),"") | Q10: =IFERROR(INDEX('12_字段字典'!$J:$J,MATCH($B10,'12_字段字典'!$B:$B,0)),"") | R10: =IFERROR(INDEX('12_字段字典'!$K:$K,MATCH($B10,'12_字段字典'!$B:$B,0)),"") | S10: =IFERROR(INDEX('12_字段字典'!$L:$L,MATCH($B10,'12_字段字典'!$B:$B,0)),"") | T10: =IFERROR(INDEX('12_字段字典'!$M:$M,MATCH($B10,'12_字段字典'!$B:$B,0)),"")
A11: A. 基本身份 | B11: reporting_period | C11: 产品报告期 | D11: reporting period | E11: 文本 | F11: 2026Q1 | G11: 2026Q1 | H11: 模板示例周期，实际应用时按产品与工厂报告期填写 | I11: 排产记录 | J11: EU+CBAM | K11: =IFERROR(INDEX('12_字段字典'!$D:$D,MATCH($B11,'12_字段字典'!$B:$B,0)),"") | L11: =IFERROR(INDEX('12_字段字典'!$E:$E,MATCH($B11,'12_字段字典'!$B:$B,0)),"") | M11: =IFERROR(INDEX('12_字段字典'!$F:$F,MATCH($B11,'12_字段字典'!$B:$B,0)),"") | N11: =IFERROR(INDEX('12_字段字典'!$G:$G,MATCH($B11,'12_字段字典'!$B:$B,0)),"") | O11: =IFERROR(INDEX('12_字段字典'!$H:$H,MATCH($B11,'12_字段字典'!$B:$B,0)),"") | P11: =IFERROR(INDEX('12_字段字典'!$I:$I,MATCH($B11,'12_字段字典'!$B:$B,0)),"") | Q11: =IFERROR(INDEX('12_字段字典'!$J:$J,MATCH($B11,'12_字段字典'!$B:$B,0)),"") | R11: =IFERROR(INDEX('12_字段字典'!$K:$K,MATCH($B11,'12_字段字典'!$B:$B,0)),"") | S11: =IFERROR(INDEX('12_字段字典'!$L:$L,MATCH($B11,'12_字段字典'!$B:$B,0)),"") | T11: =IFERROR(INDEX('12_字段字典'!$M:$M,MATCH($B11,'12_字段字典'!$B:$B,0)),"")
A12: A. 基本身份 | B12: regulatory_battery_class | C12: 监管适用类别 | D12: regulatory battery class | E12: 文本 | F12: EV battery / rechargeable industrial battery | G12: EV battery / rechargeable industrial battery | H12: 区分业务产品类别与欧盟监管适用类别，避免两者混在一起 | I12: 法规适用性说明/认证范围 | J12: EU | K12: =IFERROR(INDEX('12_字段字典'!$D:$D,MATCH($B12,'12_字段字典'!$B:$B,0)),"") | L12: =IFERROR(INDEX('12_字段字典'!$E:$E,MATCH($B12,'12_字段字典'!$B:$B,0)),"") | M12: =IFERROR(INDEX('12_字段字典'!$F:$F,MATCH($B12,'12_字段字典'!$B:$B,0)),"") | N12: =IFERROR(INDEX('12_字段字典'!$G:$G,MATCH($B12,'12_字段字典'!$B:$B,0)),"") | O12: =IFERROR(INDEX('12_字段字典'!$H:$H,MATCH($B12,'12_字段字典'!$B:$B,0)),"") | P12: =IFERROR(INDEX('12_字段字典'!$I:$I,MATCH($B12,'12_字段字典'!$B:$B,0)),"") | Q12: =IFERROR(INDEX('12_字段字典'!$J:$J,MATCH($B12,'12_字段字典'!$B:$B,0)),"") | R12: =IFERROR(INDEX('12_字段字典'!$K:$K,MATCH($B12,'12_字段字典'!$B:$B,0)),"") | S12: =IFERROR(INDEX('12_字段字典'!$L:$L,MATCH($B12,'12_字段字典'!$B:$B,0)),"") | T12: =IFERROR(INDEX('12_字段字典'!$M:$M,MATCH($B12,'12_字段字典'!$B:$B,0)),"")
A13: A. 基本身份 | B13: declared_boundary_note | C13: 申报边界说明 | D13: declared boundary note | E13: 文本 | F13: includes cell + module + pack housing + BMS + cooling within declared unit | G13: includes cell + module + pack housing + BMS + cooling within declared unit | H13: 明确申报单元到底包含哪些部件，是通用模板非常关键的边界字段 | I13: 方法学说明/BOM 边界定义 | J13: EU+CBAM | K13: =IFERROR(INDEX('12_字段字典'!$D:$D,MATCH($B13,'12_字段字典'!$B:$B,0)),"") | L13: =IFERROR(INDEX('12_字段字典'!$E:$E,MATCH($B13,'12_字段字典'!$B:$B,0)),"") | M13: =IFERROR(INDEX('12_字段字典'!$F:$F,MATCH($B13,'12_字段字典'!$B:$B,0)),"") | N13: =IFERROR(INDEX('12_字段字典'!$G:$G,MATCH($B13,'12_字段字典'!$B:$B,0)),"") | O13: =IFERROR(INDEX('12_字段字典'!$H:$H,MATCH($B13,'12_字段字典'!$B:$B,0)),"") | P13: =IFERROR(INDEX('12_字段字典'!$I:$I,MATCH($B13,'12_字段字典'!$B:$B,0)),"") | Q13: =IFERROR(INDEX('12_字段字典'!$J:$J,MATCH($B13,'12_字段字典'!$B:$B,0)),"") | R13: =IFERROR(INDEX('12_字段字典'!$K:$K,MATCH($B13,'12_字段字典'!$B:$B,0)),"") | S13: =IFERROR(INDEX('12_字段字典'!$L:$L,MATCH($B13,'12_字段字典'!$B:$B,0)),"") | T13: =IFERROR(INDEX('12_字段字典'!$M:$M,MATCH($B13,'12_字段字典'!$B:$B,0)),"")
A14: A. 基本身份 | B14: cell_count_per_unit | C14: 申报单元电芯数量 | D14: cell count per declared unit | E14: pcs/unit | F14: 120 | G14: 120 | H14: 支持从 cell 到 module、pack、system 的结构展开 | I14: BOM/结构清单 | J14: EU+CBAM | K14: =IFERROR(INDEX('12_字段字典'!$D:$D,MATCH($B14,'12_字段字典'!$B:$B,0)),"") | L14: =IFERROR(INDEX('12_字段字典'!$E:$E,MATCH($B14,'12_字段字典'!$B:$B,0)),"") | M14: =IFERROR(INDEX('12_字段字典'!$F:$F,MATCH($B14,'12_字段字典'!$B:$B,0)),"") | N14: =IFERROR(INDEX('12_字段字典'!$G:$G,MATCH($B14,'12_字段字典'!$B:$B,0)),"") | O14: =IFERROR(INDEX('12_字段字典'!$H:$H,MATCH($B14,'12_字段字典'!$B:$B,0)),"") | P14: =IFERROR(INDEX('12_字段字典'!$I:$I,MATCH($B14,'12_字段字典'!$B:$B,0)),"") | Q14: =IFERROR(INDEX('12_字段字典'!$J:$J,MATCH($B14,'12_字段字典'!$B:$B,0)),"") | R14: =IFERROR(INDEX('12_字段字典'!$K:$K,MATCH($B14,'12_字段字典'!$B:$B,0)),"") | S14: =IFERROR(INDEX('12_字段字典'!$L:$L,MATCH($B14,'12_字段字典'!$B:$B,0)),"") | T14: =IFERROR(INDEX('12_字段字典'!$M:$M,MATCH($B14,'12_字段字典'!$B:$B,0)),"")
A15: A. 基本身份 | B15: module_count_per_unit | C15: 申报单元模组数量 | D15: module count per declared unit | E15: pcs/unit | F15: 12 | G15: 12 | H15: 当申报对象是 pack 或 system 时，这个接口能避免模板只会按单层结构理解 | I15: BOM/结构清单 | J15: EU+CBAM | K15: =IFERROR(INDEX('12_字段字典'!$D:$D,MATCH($B15,'12_字段字典'!$B:$B,0)),"") | L15: =IFERROR(INDEX('12_字段字典'!$E:$E,MATCH($B15,'12_字段字典'!$B:$B,0)),"") | M15: =IFERROR(INDEX('12_字段字典'!$F:$F,MATCH($B15,'12_字段字典'!$B:$B,0)),"") | N15: =IFERROR(INDEX('12_字段字典'!$G:$G,MATCH($B15,'12_字段字典'!$B:$B,0)),"") | O15: =IFERROR(INDEX('12_字段字典'!$H:$H,MATCH($B15,'12_字段字典'!$B:$B,0)),"") | P15: =IFERROR(INDEX('12_字段字典'!$I:$I,MATCH($B15,'12_字段字典'!$B:$B,0)),"") | Q15: =IFERROR(INDEX('12_字段字典'!$J:$J,MATCH($B15,'12_字段字典'!$B:$B,0)),"") | R15: =IFERROR(INDEX('12_字段字典'!$K:$K,MATCH($B15,'12_字段字典'!$B:$B,0)),"") | S15: =IFERROR(INDEX('12_字段字典'!$L:$L,MATCH($B15,'12_字段字典'!$B:$B,0)),"") | T15: =IFERROR(INDEX('12_字段字典'!$M:$M,MATCH($B15,'12_字段字典'!$B:$B,0)),"")
A16: A. 基本身份 | B16: assembly_site_code | C16: 总成装配地点代码 | D16: assembly site code | E16: 文本 | F16: ASSEMBLY-TEMPLATE-001 | G16: ASSEMBLY-TEMPLATE-001 | H16: 支持电芯制造工厂与总成装配地点不一致的通用产品场景 | I16: 工厂主数据/制造路线 | J16: EU+CBAM | K16: =IFERROR(INDEX('12_字段字典'!$D:$D,MATCH($B16,'12_字段字典'!$B:$B,0)),"") | L16: =IFERROR(INDEX('12_字段字典'!$E:$E,MATCH($B16,'12_字段字典'!$B:$B,0)),"") | M16: =IFERROR(INDEX('12_字段字典'!$F:$F,MATCH($B16,'12_字段字典'!$B:$B,0)),"") | N16: =IFERROR(INDEX('12_字段字典'!$G:$G,MATCH($B16,'12_字段字典'!$B:$B,0)),"") | O16: =IFERROR(INDEX('12_字段字典'!$H:$H,MATCH($B16,'12_字段字典'!$B:$B,0)),"") | P16: =IFERROR(INDEX('12_字段字典'!$I:$I,MATCH($B16,'12_字段字典'!$B:$B,0)),"") | Q16: =IFERROR(INDEX('12_字段字典'!$J:$J,MATCH($B16,'12_字段字典'!$B:$B,0)),"") | R16: =IFERROR(INDEX('12_字段字典'!$K:$K,MATCH($B16,'12_字段字典'!$B:$B,0)),"") | S16: =IFERROR(INDEX('12_字段字典'!$L:$L,MATCH($B16,'12_字段字典'!$B:$B,0)),"") | T16: =IFERROR(INDEX('12_字段字典'!$M:$M,MATCH($B16,'12_字段字典'!$B:$B,0)),"")
A17: A. 基本身份 | B17: assembly_site_name | C17: 总成装配地点名称 | D17: assembly site name | E17: 文本 | F17: 某总成装配地点（模板） | G17: 某总成装配地点（模板） | H17: 若产品是系统级或 pack 级，这个字段可以承接最终装配环节 | I17: 工厂主数据/制造路线 | J17: EU+CBAM | K17: =IFERROR(INDEX('12_字段字典'!$D:$D,MATCH($B17,'12_字段字典'!$B:$B,0)),"") | L17: =IFERROR(INDEX('12_字段字典'!$E:$E,MATCH($B17,'12_字段字典'!$B:$B,0)),"") | M17: =IFERROR(INDEX('12_字段字典'!$F:$F,MATCH($B17,'12_字段字典'!$B:$B,0)),"") | N17: =IFERROR(INDEX('12_字段字典'!$G:$G,MATCH($B17,'12_字段字典'!$B:$B,0)),"") | O17: =IFERROR(INDEX('12_字段字典'!$H:$H,MATCH($B17,'12_字段字典'!$B:$B,0)),"") | P17: =IFERROR(INDEX('12_字段字典'!$I:$I,MATCH($B17,'12_字段字典'!$B:$B,0)),"") | Q17: =IFERROR(INDEX('12_字段字典'!$J:$J,MATCH($B17,'12_字段字典'!$B:$B,0)),"") | R17: =IFERROR(INDEX('12_字段字典'!$K:$K,MATCH($B17,'12_字段字典'!$B:$B,0)),"") | S17: =IFERROR(INDEX('12_字段字典'!$L:$L,MATCH($B17,'12_字段字典'!$B:$B,0)),"") | T17: =IFERROR(INDEX('12_字段字典'!$M:$M,MATCH($B17,'12_字段字典'!$B:$B,0)),"")
A18: A. 基本身份 | B18: assembly_site_country | C18: 总成装配地点国家/地区 | D18: assembly site country or region | E18: 文本 | F18: China | G18: China | H18: 便于后续扩展欧洲本地装配或多地装配的场景 | I18: 工厂主数据/制造路线 | J18: EU+CBAM | K18: =IFERROR(INDEX('12_字段字典'!$D:$D,MATCH($B18,'12_字段字典'!$B:$B,0)),"") | L18: =IFERROR(INDEX('12_字段字典'!$E:$E,MATCH($B18,'12_字段字典'!$B:$B,0)),"") | M18: =IFERROR(INDEX('12_字段字典'!$F:$F,MATCH($B18,'12_字段字典'!$B:$B,0)),"") | N18: =IFERROR(INDEX('12_字段字典'!$G:$G,MATCH($B18,'12_字段字典'!$B:$B,0)),"") | O18: =IFERROR(INDEX('12_字段字典'!$H:$H,MATCH($B18,'12_字段字典'!$B:$B,0)),"") | P18: =IFERROR(INDEX('12_字段字典'!$I:$I,MATCH($B18,'12_字段字典'!$B:$B,0)),"") | Q18: =IFERROR(INDEX('12_字段字典'!$J:$J,MATCH($B18,'12_字段字典'!$B:$B,0)),"") | R18: =IFERROR(INDEX('12_字段字典'!$K:$K,MATCH($B18,'12_字段字典'!$B:$B,0)),"") | S18: =IFERROR(INDEX('12_字段字典'!$L:$L,MATCH($B18,'12_字段字典'!$B:$B,0)),"") | T18: =IFERROR(INDEX('12_字段字典'!$M:$M,MATCH($B18,'12_字段字典'!$B:$B,0)),"")
A19: A. 基本身份 | B19: product_series | C19: 产品系列/平台 | D19: product series / platform | E19: 文本 | F19: CATL 通用产品系列（Template） | G19: CATL 通用产品系列（Template） | H19: 用于兼容不同产品线，例如神行、麒麟、储能系统等 | I19: 产品主数据 | J19: EU+CBAM | K19: =IFERROR(INDEX('12_字段字典'!$D:$D,MATCH($B19,'12_字段字典'!$B:$B,0)),"") | L19: =IFERROR(INDEX('12_字段字典'!$E:$E,MATCH($B19,'12_字段字典'!$B:$B,0)),"") | M19: =IFERROR(INDEX('12_字段字典'!$F:$F,MATCH($B19,'12_字段字典'!$B:$B,0)),"") | N19: =IFERROR(INDEX('12_字段字典'!$G:$G,MATCH($B19,'12_字段字典'!$B:$B,0)),"") | O19: =IFERROR(INDEX('12_字段字典'!$H:$H,MATCH($B19,'12_字段字典'!$B:$B,0)),"") | P19: =IFERROR(INDEX('12_字段字典'!$I:$I,MATCH($B19,'12_字段字典'!$B:$B,0)),"") | Q19: =IFERROR(INDEX('12_字段字典'!$J:$J,MATCH($B19,'12_字段字典'!$B:$B,0)),"") | R19: =IFERROR(INDEX('12_字段字典'!$K:$K,MATCH($B19,'12_字段字典'!$B:$B,0)),"") | S19: =IFERROR(INDEX('12_字段字典'!$L:$L,MATCH($B19,'12_字段字典'!$B:$B,0)),"") | T19: =IFERROR(INDEX('12_字段字典'!$M:$M,MATCH($B19,'12_字段字典'!$B:$B,0)),"")
A20: A. 基本身份 | B20: application_scenario | C20: 应用场景 | D20: application scenario | E20: 文本 | F20: EV / ESS / special application | G20: EV / ESS / special application | H20: 用于区分动力、储能或其他产品场景 | I20: 产品主数据/规格书 | J20: EU+CBAM | K20: =IFERROR(INDEX('12_字段字典'!$D:$D,MATCH($B20,'12_字段字典'!$B:$B,0)),"") | L20: =IFERROR(INDEX('12_字段字典'!$E:$E,MATCH($B20,'12_字段字典'!$B:$B,0)),"") | M20: =IFERROR(INDEX('12_字段字典'!$F:$F,MATCH($B20,'12_字段字典'!$B:$B,0)),"") | N20: =IFERROR(INDEX('12_字段字典'!$G:$G,MATCH($B20,'12_字段字典'!$B:$B,0)),"") | O20: =IFERROR(INDEX('12_字段字典'!$H:$H,MATCH($B20,'12_字段字典'!$B:$B,0)),"") | P20: =IFERROR(INDEX('12_字段字典'!$I:$I,MATCH($B20,'12_字段字典'!$B:$B,0)),"") | Q20: =IFERROR(INDEX('12_字段字典'!$J:$J,MATCH($B20,'12_字段字典'!$B:$B,0)),"") | R20: =IFERROR(INDEX('12_字段字典'!$K:$K,MATCH($B20,'12_字段字典'!$B:$B,0)),"") | S20: =IFERROR(INDEX('12_字段字典'!$L:$L,MATCH($B20,'12_字段字典'!$B:$B,0)),"") | T20: =IFERROR(INDEX('12_字段字典'!$M:$M,MATCH($B20,'12_字段字典'!$B:$B,0)),"")
A21: A. 基本身份 | B21: product_level | C21: 申报对象层级 | D21: declared product level | E21: 文本 | F21: cell / module / pack / system | G21: cell / module / pack / system | H21: 通用模板必须允许不同申报对象层级 | I21: 产品主数据/护照规则 | J21: EU+CBAM | K21: =IFERROR(INDEX('12_字段字典'!$D:$D,MATCH($B21,'12_字段字典'!$B:$B,0)),"") | L21: =IFERROR(INDEX('12_字段字典'!$E:$E,MATCH($B21,'12_字段字典'!$B:$B,0)),"") | M21: =IFERROR(INDEX('12_字段字典'!$F:$F,MATCH($B21,'12_字段字典'!$B:$B,0)),"") | N21: =IFERROR(INDEX('12_字段字典'!$G:$G,MATCH($B21,'12_字段字典'!$B:$B,0)),"") | O21: =IFERROR(INDEX('12_字段字典'!$H:$H,MATCH($B21,'12_字段字典'!$B:$B,0)),"") | P21: =IFERROR(INDEX('12_字段字典'!$I:$I,MATCH($B21,'12_字段字典'!$B:$B,0)),"") | Q21: =IFERROR(INDEX('12_字段字典'!$J:$J,MATCH($B21,'12_字段字典'!$B:$B,0)),"") | R21: =IFERROR(INDEX('12_字段字典'!$K:$K,MATCH($B21,'12_字段字典'!$B:$B,0)),"") | S21: =IFERROR(INDEX('12_字段字典'!$L:$L,MATCH($B21,'12_字段字典'!$B:$B,0)),"") | T21: =IFERROR(INDEX('12_字段字典'!$M:$M,MATCH($B21,'12_字段字典'!$B:$B,0)),"")
A22: A. 基本身份 | B22: declared_unit | C22: 申报单位 | D22: declared unit | E22: 文本 | F22: 1 battery pack / 1 system | G22: 1 battery pack / 1 system | H22: 便于未来不同产品或系统级申报 | I22: 方法学说明 | J22: EU+CBAM | K22: =IFERROR(INDEX('12_字段字典'!$D:$D,MATCH($B22,'12_字段字典'!$B:$B,0)),"") | L22: =IFERROR(INDEX('12_字段字典'!$E:$E,MATCH($B22,'12_字段字典'!$B:$B,0)),"") | M22: =IFERROR(INDEX('12_字段字典'!$F:$F,MATCH($B22,'12_字段字典'!$B:$B,0)),"") | N22: =IFERROR(INDEX('12_字段字典'!$G:$G,MATCH($B22,'12_字段字典'!$B:$B,0)),"") | O22: =IFERROR(INDEX('12_字段字典'!$H:$H,MATCH($B22,'12_字段字典'!$B:$B,0)),"") | P22: =IFERROR(INDEX('12_字段字典'!$I:$I,MATCH($B22,'12_字段字典'!$B:$B,0)),"") | Q22: =IFERROR(INDEX('12_字段字典'!$J:$J,MATCH($B22,'12_字段字典'!$B:$B,0)),"") | R22: =IFERROR(INDEX('12_字段字典'!$K:$K,MATCH($B22,'12_字段字典'!$B:$B,0)),"") | S22: =IFERROR(INDEX('12_字段字典'!$L:$L,MATCH($B22,'12_字段字典'!$B:$B,0)),"") | T22: =IFERROR(INDEX('12_字段字典'!$M:$M,MATCH($B22,'12_字段字典'!$B:$B,0)),"")
A23: A. 基本身份 | B23: destination_market | C23: 目标市场 | D23: destination market | E23: 文本 | F23: EU | G23: EU | H23: 同一模板可扩展到不同市场版本 | I23: 项目主数据 | J23: EU+CBAM | K23: =IFERROR(INDEX('12_字段字典'!$D:$D,MATCH($B23,'12_字段字典'!$B:$B,0)),"") | L23: =IFERROR(INDEX('12_字段字典'!$E:$E,MATCH($B23,'12_字段字典'!$B:$B,0)),"") | M23: =IFERROR(INDEX('12_字段字典'!$F:$F,MATCH($B23,'12_字段字典'!$B:$B,0)),"") | N23: =IFERROR(INDEX('12_字段字典'!$G:$G,MATCH($B23,'12_字段字典'!$B:$B,0)),"") | O23: =IFERROR(INDEX('12_字段字典'!$H:$H,MATCH($B23,'12_字段字典'!$B:$B,0)),"") | P23: =IFERROR(INDEX('12_字段字典'!$I:$I,MATCH($B23,'12_字段字典'!$B:$B,0)),"") | Q23: =IFERROR(INDEX('12_字段字典'!$J:$J,MATCH($B23,'12_字段字典'!$B:$B,0)),"") | R23: =IFERROR(INDEX('12_字段字典'!$K:$K,MATCH($B23,'12_字段字典'!$B:$B,0)),"") | S23: =IFERROR(INDEX('12_字段字典'!$L:$L,MATCH($B23,'12_字段字典'!$B:$B,0)),"") | T23: =IFERROR(INDEX('12_字段字典'!$M:$M,MATCH($B23,'12_字段字典'!$B:$B,0)),"")
A24: A. 基本身份 | B24: plant_country | C24: 制造工厂所在国家 | D24: plant country | E24: 文本 | F24: China | G24: China | H24: 为未来跨境工厂和欧洲本地工厂预留接口 | I24: 工厂主数据 | J24: EU+CBAM | K24: =IFERROR(INDEX('12_字段字典'!$D:$D,MATCH($B24,'12_字段字典'!$B:$B,0)),"") | L24: =IFERROR(INDEX('12_字段字典'!$E:$E,MATCH($B24,'12_字段字典'!$B:$B,0)),"") | M24: =IFERROR(INDEX('12_字段字典'!$F:$F,MATCH($B24,'12_字段字典'!$B:$B,0)),"") | N24: =IFERROR(INDEX('12_字段字典'!$G:$G,MATCH($B24,'12_字段字典'!$B:$B,0)),"") | O24: =IFERROR(INDEX('12_字段字典'!$H:$H,MATCH($B24,'12_字段字典'!$B:$B,0)),"") | P24: =IFERROR(INDEX('12_字段字典'!$I:$I,MATCH($B24,'12_字段字典'!$B:$B,0)),"") | Q24: =IFERROR(INDEX('12_字段字典'!$J:$J,MATCH($B24,'12_字段字典'!$B:$B,0)),"") | R24: =IFERROR(INDEX('12_字段字典'!$K:$K,MATCH($B24,'12_字段字典'!$B:$B,0)),"") | S24: =IFERROR(INDEX('12_字段字典'!$L:$L,MATCH($B24,'12_字段字典'!$B:$B,0)),"") | T24: =IFERROR(INDEX('12_字段字典'!$M:$M,MATCH($B24,'12_字段字典'!$B:$B,0)),"")
A25: A. 基本身份 | B25: cell_form_factor | C25: 电芯形态 | D25: cell form factor | E25: 文本 | F25: prismatic / cylindrical / pouch | G25: prismatic / cylindrical / pouch | H25: 为不同产品平台预留结构差异接口 | I25: 规格书/产品主数据 | J25: EU | K25: =IFERROR(INDEX('12_字段字典'!$D:$D,MATCH($B25,'12_字段字典'!$B:$B,0)),"") | L25: =IFERROR(INDEX('12_字段字典'!$E:$E,MATCH($B25,'12_字段字典'!$B:$B,0)),"") | M25: =IFERROR(INDEX('12_字段字典'!$F:$F,MATCH($B25,'12_字段字典'!$B:$B,0)),"") | N25: =IFERROR(INDEX('12_字段字典'!$G:$G,MATCH($B25,'12_字段字典'!$B:$B,0)),"") | O25: =IFERROR(INDEX('12_字段字典'!$H:$H,MATCH($B25,'12_字段字典'!$B:$B,0)),"") | P25: =IFERROR(INDEX('12_字段字典'!$I:$I,MATCH($B25,'12_字段字典'!$B:$B,0)),"") | Q25: =IFERROR(INDEX('12_字段字典'!$J:$J,MATCH($B25,'12_字段字典'!$B:$B,0)),"") | R25: =IFERROR(INDEX('12_字段字典'!$K:$K,MATCH($B25,'12_字段字典'!$B:$B,0)),"") | S25: =IFERROR(INDEX('12_字段字典'!$L:$L,MATCH($B25,'12_字段字典'!$B:$B,0)),"") | T25: =IFERROR(INDEX('12_字段字典'!$M:$M,MATCH($B25,'12_字段字典'!$B:$B,0)),"")
A26: A. 基本身份 | B26: architecture_type | C26: 系统架构类型 | D26: architecture type | E26: 文本 | F26: CTP / module-pack / containerized ESS | G26: CTP / module-pack / containerized ESS | H26: 避免模板只绑定到神行 CTP 场景 | I26: 技术文档/产品主数据 | J26: EU+CBAM | K26: =IFERROR(INDEX('12_字段字典'!$D:$D,MATCH($B26,'12_字段字典'!$B:$B,0)),"") | L26: =IFERROR(INDEX('12_字段字典'!$E:$E,MATCH($B26,'12_字段字典'!$B:$B,0)),"") | M26: =IFERROR(INDEX('12_字段字典'!$F:$F,MATCH($B26,'12_字段字典'!$B:$B,0)),"") | N26: =IFERROR(INDEX('12_字段字典'!$G:$G,MATCH($B26,'12_字段字典'!$B:$B,0)),"") | O26: =IFERROR(INDEX('12_字段字典'!$H:$H,MATCH($B26,'12_字段字典'!$B:$B,0)),"") | P26: =IFERROR(INDEX('12_字段字典'!$I:$I,MATCH($B26,'12_字段字典'!$B:$B,0)),"") | Q26: =IFERROR(INDEX('12_字段字典'!$J:$J,MATCH($B26,'12_字段字典'!$B:$B,0)),"") | R26: =IFERROR(INDEX('12_字段字典'!$K:$K,MATCH($B26,'12_字段字典'!$B:$B,0)),"") | S26: =IFERROR(INDEX('12_字段字典'!$L:$L,MATCH($B26,'12_字段字典'!$B:$B,0)),"") | T26: =IFERROR(INDEX('12_字段字典'!$M:$M,MATCH($B26,'12_字段字典'!$B:$B,0)),"")
A27: A. 基本身份 | B27: total_product_mass_kg | C27: 产品总质量 | D27: total product mass | E27: kg/unit | F27: 520 | G27: 520 | H27: 为不同产品级别和系统级方案预留总质量接口 | I27: 规格书/BOM | J27: EU+CBAM | K27: =IFERROR(INDEX('12_字段字典'!$D:$D,MATCH($B27,'12_字段字典'!$B:$B,0)),"") | L27: =IFERROR(INDEX('12_字段字典'!$E:$E,MATCH($B27,'12_字段字典'!$B:$B,0)),"") | M27: =IFERROR(INDEX('12_字段字典'!$F:$F,MATCH($B27,'12_字段字典'!$B:$B,0)),"") | N27: =IFERROR(INDEX('12_字段字典'!$G:$G,MATCH($B27,'12_字段字典'!$B:$B,0)),"") | O27: =IFERROR(INDEX('12_字段字典'!$H:$H,MATCH($B27,'12_字段字典'!$B:$B,0)),"") | P27: =IFERROR(INDEX('12_字段字典'!$I:$I,MATCH($B27,'12_字段字典'!$B:$B,0)),"") | Q27: =IFERROR(INDEX('12_字段字典'!$J:$J,MATCH($B27,'12_字段字典'!$B:$B,0)),"") | R27: =IFERROR(INDEX('12_字段字典'!$K:$K,MATCH($B27,'12_字段字典'!$B:$B,0)),"") | S27: =IFERROR(INDEX('12_字段字典'!$L:$L,MATCH($B27,'12_字段字典'!$B:$B,0)),"") | T27: =IFERROR(INDEX('12_字段字典'!$M:$M,MATCH($B27,'12_字段字典'!$B:$B,0)),"")
A28: A. 基本身份 | B28: pcf_method_version | C28: 碳足迹方法版本 | D28: PCF methodology version | E28: 文本 | F28: EU Battery CF Method / internal template v1 | G28: EU Battery CF Method / internal template v1 | H28: 记录当前产品采用哪一版方法学 | I28: 方法学说明/计算底稿 | J28: EU+CBAM | K28: =IFERROR(INDEX('12_字段字典'!$D:$D,MATCH($B28,'12_字段字典'!$B:$B,0)),"") | L28: =IFERROR(INDEX('12_字段字典'!$E:$E,MATCH($B28,'12_字段字典'!$B:$B,0)),"") | M28: =IFERROR(INDEX('12_字段字典'!$F:$F,MATCH($B28,'12_字段字典'!$B:$B,0)),"") | N28: =IFERROR(INDEX('12_字段字典'!$G:$G,MATCH($B28,'12_字段字典'!$B:$B,0)),"") | O28: =IFERROR(INDEX('12_字段字典'!$H:$H,MATCH($B28,'12_字段字典'!$B:$B,0)),"") | P28: =IFERROR(INDEX('12_字段字典'!$I:$I,MATCH($B28,'12_字段字典'!$B:$B,0)),"") | Q28: =IFERROR(INDEX('12_字段字典'!$J:$J,MATCH($B28,'12_字段字典'!$B:$B,0)),"") | R28: =IFERROR(INDEX('12_字段字典'!$K:$K,MATCH($B28,'12_字段字典'!$B:$B,0)),"") | S28: =IFERROR(INDEX('12_字段字典'!$L:$L,MATCH($B28,'12_字段字典'!$B:$B,0)),"") | T28: =IFERROR(INDEX('12_字段字典'!$M:$M,MATCH($B28,'12_字段字典'!$B:$B,0)),"")
A29: A. 基本身份 | B29: factor_library_version | C29: 因子库版本 | D29: factor library version | E29: 文本 | F29: Factor Library v1.0 | G29: Factor Library v1.0 | H29: 为中欧因子口径转换和版本管理预留接口 | I29: 因子库/方法说明 | J29: EU+CBAM | K29: =IFERROR(INDEX('12_字段字典'!$D:$D,MATCH($B29,'12_字段字典'!$B:$B,0)),"") | L29: =IFERROR(INDEX('12_字段字典'!$E:$E,MATCH($B29,'12_字段字典'!$B:$B,0)),"") | M29: =IFERROR(INDEX('12_字段字典'!$F:$F,MATCH($B29,'12_字段字典'!$B:$B,0)),"") | N29: =IFERROR(INDEX('12_字段字典'!$G:$G,MATCH($B29,'12_字段字典'!$B:$B,0)),"") | O29: =IFERROR(INDEX('12_字段字典'!$H:$H,MATCH($B29,'12_字段字典'!$B:$B,0)),"") | P29: =IFERROR(INDEX('12_字段字典'!$I:$I,MATCH($B29,'12_字段字典'!$B:$B,0)),"") | Q29: =IFERROR(INDEX('12_字段字典'!$J:$J,MATCH($B29,'12_字段字典'!$B:$B,0)),"") | R29: =IFERROR(INDEX('12_字段字典'!$K:$K,MATCH($B29,'12_字段字典'!$B:$B,0)),"") | S29: =IFERROR(INDEX('12_字段字典'!$L:$L,MATCH($B29,'12_字段字典'!$B:$B,0)),"") | T29: =IFERROR(INDEX('12_字段字典'!$M:$M,MATCH($B29,'12_字段字典'!$B:$B,0)),"")
A30: A. 基本身份 | B30: verification_report_id | C30: 核验报告编号 | D30: verification report ID | E30: 文本 | F30: VERIFY-TEMPLATE-001 | G30: VERIFY-TEMPLATE-001 | H30: 便于后续把第三方核验真正挂接到字段层 | I30: 核验声明/第三方报告 | J30: EU+CBAM | K30: =IFERROR(INDEX('12_字段字典'!$D:$D,MATCH($B30,'12_字段字典'!$B:$B,0)),"") | L30: =IFERROR(INDEX('12_字段字典'!$E:$E,MATCH($B30,'12_字段字典'!$B:$B,0)),"") | M30: =IFERROR(INDEX('12_字段字典'!$F:$F,MATCH($B30,'12_字段字典'!$B:$B,0)),"") | N30: =IFERROR(INDEX('12_字段字典'!$G:$G,MATCH($B30,'12_字段字典'!$B:$B,0)),"") | O30: =IFERROR(INDEX('12_字段字典'!$H:$H,MATCH($B30,'12_字段字典'!$B:$B,0)),"") | P30: =IFERROR(INDEX('12_字段字典'!$I:$I,MATCH($B30,'12_字段字典'!$B:$B,0)),"") | Q30: =IFERROR(INDEX('12_字段字典'!$J:$J,MATCH($B30,'12_字段字典'!$B:$B,0)),"") | R30: =IFERROR(INDEX('12_字段字典'!$K:$K,MATCH($B30,'12_字段字典'!$B:$B,0)),"") | S30: =IFERROR(INDEX('12_字段字典'!$L:$L,MATCH($B30,'12_字段字典'!$B:$B,0)),"") | T30: =IFERROR(INDEX('12_字段字典'!$M:$M,MATCH($B30,'12_字段字典'!$B:$B,0)),"")
A31: A. 基本身份 | B31: pack_capacity_kwh | C31: 申报单元额定容量 | D31: declared unit capacity | E31: kWh/declared unit | F31: 60 | G31: 60 | H31: 无论当前申报对象是 cell、module、pack 还是 system，都按当前申报单元填写容量 | I31: 规格书/测试报告 | J31: EU | K31: =IFERROR(INDEX('12_字段字典'!$D:$D,MATCH($B31,'12_字段字典'!$B:$B,0)),"") | L31: =IFERROR(INDEX('12_字段字典'!$E:$E,MATCH($B31,'12_字段字典'!$B:$B,0)),"") | M31: =IFERROR(INDEX('12_字段字典'!$F:$F,MATCH($B31,'12_字段字典'!$B:$B,0)),"") | N31: =IFERROR(INDEX('12_字段字典'!$G:$G,MATCH($B31,'12_字段字典'!$B:$B,0)),"") | O31: =IFERROR(INDEX('12_字段字典'!$H:$H,MATCH($B31,'12_字段字典'!$B:$B,0)),"") | P31: =IFERROR(INDEX('12_字段字典'!$I:$I,MATCH($B31,'12_字段字典'!$B:$B,0)),"") | Q31: =IFERROR(INDEX('12_字段字典'!$J:$J,MATCH($B31,'12_字段字典'!$B:$B,0)),"") | R31: =IFERROR(INDEX('12_字段字典'!$K:$K,MATCH($B31,'12_字段字典'!$B:$B,0)),"") | S31: =IFERROR(INDEX('12_字段字典'!$L:$L,MATCH($B31,'12_字段字典'!$B:$B,0)),"") | T31: =IFERROR(INDEX('12_字段字典'!$M:$M,MATCH($B31,'12_字段字典'!$B:$B,0)),"")
A32: A. 基本身份 | B32: nominal_voltage_v | C32: 标称电压 | D32: nominal voltage | E32: V | F32: 400 | G32: 400 | H32: 产品公开参数 | I32: 规格书/测试报告 | J32: EU | K32: =IFERROR(INDEX('12_字段字典'!$D:$D,MATCH($B32,'12_字段字典'!$B:$B,0)),"") | L32: =IFERROR(INDEX('12_字段字典'!$E:$E,MATCH($B32,'12_字段字典'!$B:$B,0)),"") | M32: =IFERROR(INDEX('12_字段字典'!$F:$F,MATCH($B32,'12_字段字典'!$B:$B,0)),"") | N32: =IFERROR(INDEX('12_字段字典'!$G:$G,MATCH($B32,'12_字段字典'!$B:$B,0)),"") | O32: =IFERROR(INDEX('12_字段字典'!$H:$H,MATCH($B32,'12_字段字典'!$B:$B,0)),"") | P32: =IFERROR(INDEX('12_字段字典'!$I:$I,MATCH($B32,'12_字段字典'!$B:$B,0)),"") | Q32: =IFERROR(INDEX('12_字段字典'!$J:$J,MATCH($B32,'12_字段字典'!$B:$B,0)),"") | R32: =IFERROR(INDEX('12_字段字典'!$K:$K,MATCH($B32,'12_字段字典'!$B:$B,0)),"") | S32: =IFERROR(INDEX('12_字段字典'!$L:$L,MATCH($B32,'12_字段字典'!$B:$B,0)),"") | T32: =IFERROR(INDEX('12_字段字典'!$M:$M,MATCH($B32,'12_字段字典'!$B:$B,0)),"")
A33: A. 基本身份 | B33: cycle_life_cycles | C33: 循环寿命 | D33: cycle life | E33: cycles | F33: 3000 | G33: 3000 | H33: 护照参数层 | I33: 测试报告 | J33: EU | K33: =IFERROR(INDEX('12_字段字典'!$D:$D,MATCH($B33,'12_字段字典'!$B:$B,0)),"") | L33: =IFERROR(INDEX('12_字段字典'!$E:$E,MATCH($B33,'12_字段字典'!$B:$B,0)),"") | M33: =IFERROR(INDEX('12_字段字典'!$F:$F,MATCH($B33,'12_字段字典'!$B:$B,0)),"") | N33: =IFERROR(INDEX('12_字段字典'!$G:$G,MATCH($B33,'12_字段字典'!$B:$B,0)),"") | O33: =IFERROR(INDEX('12_字段字典'!$H:$H,MATCH($B33,'12_字段字典'!$B:$B,0)),"") | P33: =IFERROR(INDEX('12_字段字典'!$I:$I,MATCH($B33,'12_字段字典'!$B:$B,0)),"") | Q33: =IFERROR(INDEX('12_字段字典'!$J:$J,MATCH($B33,'12_字段字典'!$B:$B,0)),"") | R33: =IFERROR(INDEX('12_字段字典'!$K:$K,MATCH($B33,'12_字段字典'!$B:$B,0)),"") | S33: =IFERROR(INDEX('12_字段字典'!$L:$L,MATCH($B33,'12_字段字典'!$B:$B,0)),"") | T33: =IFERROR(INDEX('12_字段字典'!$M:$M,MATCH($B33,'12_字段字典'!$B:$B,0)),"")
A34: A. 基本身份 | B34: individual_battery_prefix | C34: 个体电池编码前缀 | D34: battery prefix | E34: 文本 | F34: GEN26Q1 | G34: GEN26Q1 | H34: 模板前缀，后续可扩展为任意序列化规则 | I34: 序列化规则 | J34: EU | K34: =IFERROR(INDEX('12_字段字典'!$D:$D,MATCH($B34,'12_字段字典'!$B:$B,0)),"") | L34: =IFERROR(INDEX('12_字段字典'!$E:$E,MATCH($B34,'12_字段字典'!$B:$B,0)),"") | M34: =IFERROR(INDEX('12_字段字典'!$F:$F,MATCH($B34,'12_字段字典'!$B:$B,0)),"") | N34: =IFERROR(INDEX('12_字段字典'!$G:$G,MATCH($B34,'12_字段字典'!$B:$B,0)),"") | O34: =IFERROR(INDEX('12_字段字典'!$H:$H,MATCH($B34,'12_字段字典'!$B:$B,0)),"") | P34: =IFERROR(INDEX('12_字段字典'!$I:$I,MATCH($B34,'12_字段字典'!$B:$B,0)),"") | Q34: =IFERROR(INDEX('12_字段字典'!$J:$J,MATCH($B34,'12_字段字典'!$B:$B,0)),"") | R34: =IFERROR(INDEX('12_字段字典'!$K:$K,MATCH($B34,'12_字段字典'!$B:$B,0)),"") | S34: =IFERROR(INDEX('12_字段字典'!$L:$L,MATCH($B34,'12_字段字典'!$B:$B,0)),"") | T34: =IFERROR(INDEX('12_字段字典'!$M:$M,MATCH($B34,'12_字段字典'!$B:$B,0)),"")
A35: A. 基本身份 | B35: due_diligence_policy_url | C35: 尽调政策链接 | D35: due diligence policy URL | E35: 文本 | F35: https://www.catl.com/ | G35: https://www.catl.com/ | H35: 尽调公开字段 | I35: 政策文件/官网 | J35: EU | K35: =IFERROR(INDEX('12_字段字典'!$D:$D,MATCH($B35,'12_字段字典'!$B:$B,0)),"") | L35: =IFERROR(INDEX('12_字段字典'!$E:$E,MATCH($B35,'12_字段字典'!$B:$B,0)),"") | M35: =IFERROR(INDEX('12_字段字典'!$F:$F,MATCH($B35,'12_字段字典'!$B:$B,0)),"") | N35: =IFERROR(INDEX('12_字段字典'!$G:$G,MATCH($B35,'12_字段字典'!$B:$B,0)),"") | O35: =IFERROR(INDEX('12_字段字典'!$H:$H,MATCH($B35,'12_字段字典'!$B:$B,0)),"") | P35: =IFERROR(INDEX('12_字段字典'!$I:$I,MATCH($B35,'12_字段字典'!$B:$B,0)),"") | Q35: =IFERROR(INDEX('12_字段字典'!$J:$J,MATCH($B35,'12_字段字典'!$B:$B,0)),"") | R35: =IFERROR(INDEX('12_字段字典'!$K:$K,MATCH($B35,'12_字段字典'!$B:$B,0)),"") | S35: =IFERROR(INDEX('12_字段字典'!$L:$L,MATCH($B35,'12_字段字典'!$B:$B,0)),"") | T35: =IFERROR(INDEX('12_字段字典'!$M:$M,MATCH($B35,'12_字段字典'!$B:$B,0)),"")
A36: A. 基本身份 | B36: qr_object_id | C36: 护照对象 ID | D36: passport object id | E36: 文本 | F36: passport-generic-template-001 | G36: passport-generic-template-001 | H36: 数字护照对象键 | I36: 护照系统对象 ID | J36: EU | K36: =IFERROR(INDEX('12_字段字典'!$D:$D,MATCH($B36,'12_字段字典'!$B:$B,0)),"") | L36: =IFERROR(INDEX('12_字段字典'!$E:$E,MATCH($B36,'12_字段字典'!$B:$B,0)),"") | M36: =IFERROR(INDEX('12_字段字典'!$F:$F,MATCH($B36,'12_字段字典'!$B:$B,0)),"") | N36: =IFERROR(INDEX('12_字段字典'!$G:$G,MATCH($B36,'12_字段字典'!$B:$B,0)),"") | O36: =IFERROR(INDEX('12_字段字典'!$H:$H,MATCH($B36,'12_字段字典'!$B:$B,0)),"") | P36: =IFERROR(INDEX('12_字段字典'!$I:$I,MATCH($B36,'12_字段字典'!$B:$B,0)),"") | Q36: =IFERROR(INDEX('12_字段字典'!$J:$J,MATCH($B36,'12_字段字典'!$B:$B,0)),"") | R36: =IFERROR(INDEX('12_字段字典'!$K:$K,MATCH($B36,'12_字段字典'!$B:$B,0)),"") | S36: =IFERROR(INDEX('12_字段字典'!$L:$L,MATCH($B36,'12_字段字典'!$B:$B,0)),"") | T36: =IFERROR(INDEX('12_字段字典'!$M:$M,MATCH($B36,'12_字段字典'!$B:$B,0)),"")
A37: B. 合规准备状态 | B37: pcf_study_status | C37: 产品碳足迹研究底稿状态 | D37: PCF study status | E37: 文本 | F37: 齐备 | G37: 齐备 | H37: 碳足迹声明底稿是否齐备 | I37: PCF 研究底稿 | J37: EU | K37: =IFERROR(INDEX('12_字段字典'!$D:$D,MATCH($B37,'12_字段字典'!$B:$B,0)),"") | L37: =IFERROR(INDEX('12_字段字典'!$E:$E,MATCH($B37,'12_字段字典'!$B:$B,0)),"") | M37: =IFERROR(INDEX('12_字段字典'!$F:$F,MATCH($B37,'12_字段字典'!$B:$B,0)),"") | N37: =IFERROR(INDEX('12_字段字典'!$G:$G,MATCH($B37,'12_字段字典'!$B:$B,0)),"") | O37: =IFERROR(INDEX('12_字段字典'!$H:$H,MATCH($B37,'12_字段字典'!$B:$B,0)),"") | P37: =IFERROR(INDEX('12_字段字典'!$I:$I,MATCH($B37,'12_字段字典'!$B:$B,0)),"") | Q37: =IFERROR(INDEX('12_字段字典'!$J:$J,MATCH($B37,'12_字段字典'!$B:$B,0)),"") | R37: =IFERROR(INDEX('12_字段字典'!$K:$K,MATCH($B37,'12_字段字典'!$B:$B,0)),"") | S37: =IFERROR(INDEX('12_字段字典'!$L:$L,MATCH($B37,'12_字段字典'!$B:$B,0)),"") | T37: =IFERROR(INDEX('12_字段字典'!$M:$M,MATCH($B37,'12_字段字典'!$B:$B,0)),"")
A38: B. 合规准备状态 | B38: test_report_status | C38: 测试报告状态 | D38: test report status | E38: 文本 | F38: 齐备 | G38: 齐备 | H38: 正式合规评估硬材料 | I38: 测试报告原件 | J38: EU | K38: =IFERROR(INDEX('12_字段字典'!$D:$D,MATCH($B38,'12_字段字典'!$B:$B,0)),"") | L38: =IFERROR(INDEX('12_字段字典'!$E:$E,MATCH($B38,'12_字段字典'!$B:$B,0)),"") | M38: =IFERROR(INDEX('12_字段字典'!$F:$F,MATCH($B38,'12_字段字典'!$B:$B,0)),"") | N38: =IFERROR(INDEX('12_字段字典'!$G:$G,MATCH($B38,'12_字段字典'!$B:$B,0)),"") | O38: =IFERROR(INDEX('12_字段字典'!$H:$H,MATCH($B38,'12_字段字典'!$B:$B,0)),"") | P38: =IFERROR(INDEX('12_字段字典'!$I:$I,MATCH($B38,'12_字段字典'!$B:$B,0)),"") | Q38: =IFERROR(INDEX('12_字段字典'!$J:$J,MATCH($B38,'12_字段字典'!$B:$B,0)),"") | R38: =IFERROR(INDEX('12_字段字典'!$K:$K,MATCH($B38,'12_字段字典'!$B:$B,0)),"") | S38: =IFERROR(INDEX('12_字段字典'!$L:$L,MATCH($B38,'12_字段字典'!$B:$B,0)),"") | T38: =IFERROR(INDEX('12_字段字典'!$M:$M,MATCH($B38,'12_字段字典'!$B:$B,0)),"")
A39: B. 合规准备状态 | B39: technical_doc_status | C39: 技术文档状态 | D39: technical documentation status | E39: 文本 | F39: 齐备 | G39: 齐备 | H39: Annex VIII 关键材料 | I39: 图纸/说明书/计算书 | J39: EU | K39: =IFERROR(INDEX('12_字段字典'!$D:$D,MATCH($B39,'12_字段字典'!$B:$B,0)),"") | L39: =IFERROR(INDEX('12_字段字典'!$E:$E,MATCH($B39,'12_字段字典'!$B:$B,0)),"") | M39: =IFERROR(INDEX('12_字段字典'!$F:$F,MATCH($B39,'12_字段字典'!$B:$B,0)),"") | N39: =IFERROR(INDEX('12_字段字典'!$G:$G,MATCH($B39,'12_字段字典'!$B:$B,0)),"") | O39: =IFERROR(INDEX('12_字段字典'!$H:$H,MATCH($B39,'12_字段字典'!$B:$B,0)),"") | P39: =IFERROR(INDEX('12_字段字典'!$I:$I,MATCH($B39,'12_字段字典'!$B:$B,0)),"") | Q39: =IFERROR(INDEX('12_字段字典'!$J:$J,MATCH($B39,'12_字段字典'!$B:$B,0)),"") | R39: =IFERROR(INDEX('12_字段字典'!$K:$K,MATCH($B39,'12_字段字典'!$B:$B,0)),"") | S39: =IFERROR(INDEX('12_字段字典'!$L:$L,MATCH($B39,'12_字段字典'!$B:$B,0)),"") | T39: =IFERROR(INDEX('12_字段字典'!$M:$M,MATCH($B39,'12_字段字典'!$B:$B,0)),"")
A40: B. 合规准备状态 | B40: third_party_verification_status | C40: 第三方核验状态 | D40: third-party verification status | E40: 文本 | F40: 已核验 | G40: 已核验 | H40: 碳足迹/再生料/上游 PCF 关键状态 | I40: 核验声明 | J40: EU+CBAM | K40: =IFERROR(INDEX('12_字段字典'!$D:$D,MATCH($B40,'12_字段字典'!$B:$B,0)),"") | L40: =IFERROR(INDEX('12_字段字典'!$E:$E,MATCH($B40,'12_字段字典'!$B:$B,0)),"") | M40: =IFERROR(INDEX('12_字段字典'!$F:$F,MATCH($B40,'12_字段字典'!$B:$B,0)),"") | N40: =IFERROR(INDEX('12_字段字典'!$G:$G,MATCH($B40,'12_字段字典'!$B:$B,0)),"") | O40: =IFERROR(INDEX('12_字段字典'!$H:$H,MATCH($B40,'12_字段字典'!$B:$B,0)),"") | P40: =IFERROR(INDEX('12_字段字典'!$I:$I,MATCH($B40,'12_字段字典'!$B:$B,0)),"") | Q40: =IFERROR(INDEX('12_字段字典'!$J:$J,MATCH($B40,'12_字段字典'!$B:$B,0)),"") | R40: =IFERROR(INDEX('12_字段字典'!$K:$K,MATCH($B40,'12_字段字典'!$B:$B,0)),"") | S40: =IFERROR(INDEX('12_字段字典'!$L:$L,MATCH($B40,'12_字段字典'!$B:$B,0)),"") | T40: =IFERROR(INDEX('12_字段字典'!$M:$M,MATCH($B40,'12_字段字典'!$B:$B,0)),"")
...

Sheet 02_欧盟电池法输出
A1: 02_欧盟电池法输出（全部自动公式）
A2: 说明：本 Sheet 不允许手动输入，只展示系统自动生成的结果。
A3: 模块 | B3: 输出字段 | C3: 单位 | D3: 自动输出值 | E3: 证据状态 | F3: 核验层级 | G3: 访问层级 | H3: 当前状态
A4: 基本信息 | B4: 制造商名称 | C4: 文本 | D4: =IFERROR(INDEX('09_EU中间表'!$D:$D,MATCH(B4,'09_EU中间表'!$B:$B,0)),"") | E4: =IFERROR(INDEX('05_证据映射过程'!$E:$E,MATCH(B4,'05_证据映射过程'!$B:$B,0)),"不适用/默认") | F4: =IFERROR(INDEX('06_核验映射过程'!$D:$D,MATCH(B4,'06_核验映射过程'!$B:$B,0)),"默认") | G4: =IFERROR(INDEX('07_权限映射过程'!$D:$D,MATCH(B4,'07_权限映射过程'!$B:$B,0)),"默认") | H4: =IF(D4="","待生成","已生成")
A5: 基本信息 | B5: 产品名称 | C5: 文本 | D5: =IFERROR(INDEX('09_EU中间表'!$D:$D,MATCH(B5,'09_EU中间表'!$B:$B,0)),"") | E5: =IFERROR(INDEX('05_证据映射过程'!$E:$E,MATCH(B5,'05_证据映射过程'!$B:$B,0)),"不适用/默认") | F5: =IFERROR(INDEX('06_核验映射过程'!$D:$D,MATCH(B5,'06_核验映射过程'!$B:$B,0)),"默认") | G5: =IFERROR(INDEX('07_权限映射过程'!$D:$D,MATCH(B5,'07_权限映射过程'!$B:$B,0)),"默认") | H5: =IF(D5="","待生成","已生成")
A6: 基本信息 | B6: 电池型号 | C6: 文本 | D6: =IFERROR(INDEX('09_EU中间表'!$D:$D,MATCH(B6,'09_EU中间表'!$B:$B,0)),"") | E6: =IFERROR(INDEX('05_证据映射过程'!$E:$E,MATCH(B6,'05_证据映射过程'!$B:$B,0)),"不适用/默认") | F6: =IFERROR(INDEX('06_核验映射过程'!$D:$D,MATCH(B6,'06_核验映射过程'!$B:$B,0)),"默认") | G6: =IFERROR(INDEX('07_权限映射过程'!$D:$D,MATCH(B6,'07_权限映射过程'!$B:$B,0)),"默认") | H6: =IF(D6="","待生成","已生成")
A7: 基本信息 | B7: 产品类别 | C7: 文本 | D7: =IFERROR(INDEX('09_EU中间表'!$D:$D,MATCH(B7,'09_EU中间表'!$B:$B,0)),"") | E7: =IFERROR(INDEX('05_证据映射过程'!$E:$E,MATCH(B7,'05_证据映射过程'!$B:$B,0)),"不适用/默认") | F7: =IFERROR(INDEX('06_核验映射过程'!$D:$D,MATCH(B7,'06_核验映射过程'!$B:$B,0)),"默认") | G7: =IFERROR(INDEX('07_权限映射过程'!$D:$D,MATCH(B7,'07_权限映射过程'!$B:$B,0)),"默认") | H7: =IF(D7="","待生成","已生成")
A8: 基本信息 | B8: 化学体系 | C8: 文本 | D8: =IFERROR(INDEX('09_EU中间表'!$D:$D,MATCH(B8,'09_EU中间表'!$B:$B,0)),"") | E8: =IFERROR(INDEX('05_证据映射过程'!$E:$E,MATCH(B8,'05_证据映射过程'!$B:$B,0)),"不适用/默认") | F8: =IFERROR(INDEX('06_核验映射过程'!$D:$D,MATCH(B8,'06_核验映射过程'!$B:$B,0)),"默认") | G8: =IFERROR(INDEX('07_权限映射过程'!$D:$D,MATCH(B8,'07_权限映射过程'!$B:$B,0)),"默认") | H8: =IF(D8="","待生成","已生成")
A9: 基本信息 | B9: 制造工厂代码 | C9: 文本 | D9: =IFERROR(INDEX('09_EU中间表'!$D:$D,MATCH(B9,'09_EU中间表'!$B:$B,0)),"") | E9: =IFERROR(INDEX('05_证据映射过程'!$E:$E,MATCH(B9,'05_证据映射过程'!$B:$B,0)),"不适用/默认") | F9: =IFERROR(INDEX('06_核验映射过程'!$D:$D,MATCH(B9,'06_核验映射过程'!$B:$B,0)),"默认") | G9: =IFERROR(INDEX('07_权限映射过程'!$D:$D,MATCH(B9,'07_权限映射过程'!$B:$B,0)),"默认") | H9: =IF(D9="","待生成","已生成")
A10: 基本信息 | B10: 制造工厂名称 | C10: 文本 | D10: =IFERROR(INDEX('09_EU中间表'!$D:$D,MATCH(B10,'09_EU中间表'!$B:$B,0)),"") | E10: =IFERROR(INDEX('05_证据映射过程'!$E:$E,MATCH(B10,'05_证据映射过程'!$B:$B,0)),"不适用/默认") | F10: =IFERROR(INDEX('06_核验映射过程'!$D:$D,MATCH(B10,'06_核验映射过程'!$B:$B,0)),"默认") | G10: =IFERROR(INDEX('07_权限映射过程'!$D:$D,MATCH(B10,'07_权限映射过程'!$B:$B,0)),"默认") | H10: =IF(D10="","待生成","已生成")
A11: 基本信息 | B11: 报告期 | C11: 文本 | D11: =IFERROR(INDEX('09_EU中间表'!$D:$D,MATCH(B11,'09_EU中间表'!$B:$B,0)),"") | E11: =IFERROR(INDEX('05_证据映射过程'!$E:$E,MATCH(B11,'05_证据映射过程'!$B:$B,0)),"不适用/默认") | F11: =IFERROR(INDEX('06_核验映射过程'!$D:$D,MATCH(B11,'06_核验映射过程'!$B:$B,0)),"默认") | G11: =IFERROR(INDEX('07_权限映射过程'!$D:$D,MATCH(B11,'07_权限映射过程'!$B:$B,0)),"默认") | H11: =IF(D11="","待生成","已生成")
A12: 产品参数 | B12: 申报单元申报单元额定容量(kWh) | C12: kWh | D12: =IFERROR(INDEX('09_EU中间表'!$D:$D,MATCH(B12,'09_EU中间表'!$B:$B,0)),"") | E12: =IFERROR(INDEX('05_证据映射过程'!$E:$E,MATCH(B12,'05_证据映射过程'!$B:$B,0)),"不适用/默认") | F12: =IFERROR(INDEX('06_核验映射过程'!$D:$D,MATCH(B12,'06_核验映射过程'!$B:$B,0)),"默认") | G12: =IFERROR(INDEX('07_权限映射过程'!$D:$D,MATCH(B12,'07_权限映射过程'!$B:$B,0)),"默认") | H12: =IF(D12="","待生成","已生成")
A13: 产品参数 | B13: 标称电压(V) | C13: V | D13: =IFERROR(INDEX('09_EU中间表'!$D:$D,MATCH(B13,'09_EU中间表'!$B:$B,0)),"") | E13: =IFERROR(INDEX('05_证据映射过程'!$E:$E,MATCH(B13,'05_证据映射过程'!$B:$B,0)),"不适用/默认") | F13: =IFERROR(INDEX('06_核验映射过程'!$D:$D,MATCH(B13,'06_核验映射过程'!$B:$B,0)),"默认") | G13: =IFERROR(INDEX('07_权限映射过程'!$D:$D,MATCH(B13,'07_权限映射过程'!$B:$B,0)),"默认") | H13: =IF(D13="","待生成","已生成")
A14: 产品参数 | B14: 循环寿命(cycles) | C14: cycles | D14: =IFERROR(INDEX('09_EU中间表'!$D:$D,MATCH(B14,'09_EU中间表'!$B:$B,0)),"") | E14: =IFERROR(INDEX('05_证据映射过程'!$E:$E,MATCH(B14,'05_证据映射过程'!$B:$B,0)),"不适用/默认") | F14: =IFERROR(INDEX('06_核验映射过程'!$D:$D,MATCH(B14,'06_核验映射过程'!$B:$B,0)),"默认") | G14: =IFERROR(INDEX('07_权限映射过程'!$D:$D,MATCH(B14,'07_权限映射过程'!$B:$B,0)),"默认") | H14: =IF(D14="","待生成","已生成")
A15: 碳足迹 | B15: 声明总碳足迹(kgCO2e/申报单元) | C15: kgCO2e/declared unit | D15: =IFERROR(INDEX('09_EU中间表'!$D:$D,MATCH(B15,'09_EU中间表'!$B:$B,0)),"") | E15: =IFERROR(INDEX('05_证据映射过程'!$E:$E,MATCH(B15,'05_证据映射过程'!$B:$B,0)),"不适用/默认") | F15: =IFERROR(INDEX('06_核验映射过程'!$D:$D,MATCH(B15,'06_核验映射过程'!$B:$B,0)),"默认") | G15: =IFERROR(INDEX('07_权限映射过程'!$D:$D,MATCH(B15,'07_权限映射过程'!$B:$B,0)),"默认") | H15: =IF(D15="","待生成","已生成")
... A34: 综合状态 | B34: EU 输出结论 | C34: 文本 | D34: =IFERROR(INDEX('09_EU中间表'!$D:$D,MATCH(B34,'09_EU中间表'!$B:$B,0)),"") | E34: =IFERROR(INDEX('05_证据映射过程'!$E:$E,MATCH(B34,'05_证据映射过程'!$B:$B,0)),"不适用/默认") | F34: =IFERROR(INDEX('06_核验映射过程'!$D:$D,MATCH(B34,'06_核验映射过程'!$B:$B,0)),"默认") | G34: =IFERROR(INDEX('07_权限映射过程'!$D:$D,MATCH(B34,'07_权限映射过程'!$B:$B,0)),"默认") | H34: =IF(D34="","待生成","已生成")

Sheet 03_CBAM输出
A1: 03_CBAM输出（全部自动公式）
A2: 说明：本 Sheet 不允许手动输入，只展示系统自动生成的结果。
A3: 模块 | B3: 输出字段 | C3: 单位 | D3: 自动输出值 | E3: 证据状态 | F3: 核验层级 | G3: 访问层级 | H3: 当前状态
A4: 基础锚点 | B4: 电池型号 | C4: 文本 | D4: =IFERROR(INDEX('10_CBAM中间表'!$D:$D,MATCH(B4,'10_CBAM中间表'!$B:$B,0)),"") | E4: =IFERROR(INDEX('05_证据映射过程'!$E:$E,MATCH(B4,'05_证据映射过程'!$B:$B,0)),"不适用/默认") | F4: =IFERROR(INDEX('06_核验映射过程'!$D:$D,MATCH(B4,'06_核验映射过程'!$B:$B,0)),"默认") | G4: =IFERROR(INDEX('07_权限映射过程'!$D:$D,MATCH(B4,'07_权限映射过程'!$B:$B,0)),"默认") | H4: =IF(D4="","待生成","已生成")
A5: 基础锚点 | B5: 产品报告期 | C5: 文本 | D5: =IFERROR(INDEX('10_CBAM中间表'!$D:$D,MATCH(B5,'10_CBAM中间表'!$B:$B,0)),"") | E5: =IFERROR(INDEX('05_证据映射过程'!$E:$E,MATCH(B5,'05_证据映射过程'!$B:$B,0)),"不适用/默认") | F5: =IFERROR(INDEX('06_核验映射过程'!$D:$D,MATCH(B5,'06_核验映射过程'!$B:$B,0)),"默认") | G5: =IFERROR(INDEX('07_权限映射过程'!$D:$D,MATCH(B5,'07_权限映射过程'!$B:$B,0)),"默认") | H5: =IF(D5="","待生成","已生成")
A6: 基础锚点 | B6: 上游材料报告期 | C6: 文本 | D6: =IFERROR(INDEX('10_CBAM中间表'!$D:$D,MATCH(B6,'10_CBAM中间表'!$B:$B,0)),"") | E6: =IFERROR(INDEX('05_证据映射过程'!$E:$E,MATCH(B6,'05_证据映射过程'!$B:$B,0)),"不适用/默认") | F6: =IFERROR(INDEX('06_核验映射过程'!$D:$D,MATCH(B6,'06_核验映射过程'!$B:$B,0)),"默认") | G6: =IFERROR(INDEX('07_权限映射过程'!$D:$D,MATCH(B6,'07_权限映射过程'!$B:$B,0)),"默认") | H6: =IF(D6="","待生成","已生成")
A7: 铝材模块 | B7: 铝材供应商安装点 ID | C7: 文本 | D7: =IFERROR(INDEX('10_CBAM中间表'!$D:$D,MATCH(B7,'10_CBAM中间表'!$B:$B,0)),"") | E7: =IFERROR(INDEX('05_证据映射过程'!$E:$E,MATCH(B7,'05_证据映射过程'!$B:$B,0)),"不适用/默认") | F7: =IFERROR(INDEX('06_核验映射过程'!$D:$D,MATCH(B7,'06_核验映射过程'!$B:$B,0)),"默认") | G7: =IFERROR(INDEX('07_权限映射过程'!$D:$D,MATCH(B7,'07_权限映射过程'!$B:$B,0)),"默认") | H7: =IF(D7="","待生成","已生成")
A8: 铝材模块 | B8: 铝材质量(kg) | C8: kg | D8: =IFERROR(INDEX('10_CBAM中间表'!$D:$D,MATCH(B8,'10_CBAM中间表'!$B:$B,0)),"") | E8: =IFERROR(INDEX('05_证据映射过程'!$E:$E,MATCH(B8,'05_证据映射过程'!$B:$B,0)),"不适用/默认") | F8: =IFERROR(INDEX('06_核验映射过程'!$D:$D,MATCH(B8,'06_核验映射过程'!$B:$B,0)),"默认") | G8: =IFERROR(INDEX('07_权限映射过程'!$D:$D,MATCH(B8,'07_权限映射过程'!$B:$B,0)),"默认") | H8: =IF(D8="","待生成","已生成")
A9: 铝材模块 | B9: 铝材直接排放因子(kgCO2e/kg) | C9: kgCO2e/kg | D9: =IFERROR(INDEX('10_CBAM中间表'!$D:$D,MATCH(B9,'10_CBAM中间表'!$B:$B,0)),"") | E9: =IFERROR(INDEX('05_证据映射过程'!$E:$E,MATCH(B9,'05_证据映射过程'!$B:$B,0)),"不适用/默认") | F9: =IFERROR(INDEX('06_核验映射过程'!$D:$D,MATCH(B9,'06_核验映射过程'!$B:$B,0)),"默认") | G9: =IFERROR(INDEX('07_权限映射过程'!$D:$D,MATCH(B9,'07_权限映射过程'!$B:$B,0)),"默认") | H9: =IF(D9="","待生成","已生成")
A10: 铝材模块 | B10: 铝材间接排放因子(kgCO2e/kg) | C10: kgCO2e/kg | D10: =IFERROR(INDEX('10_CBAM中间表'!$D:$D,MATCH(B10,'10_CBAM中间表'!$B:$B,0)),"") | E10: =IFERROR(INDEX('05_证据映射过程'!$E:$E,MATCH(B10,'05_证据映射过程'!$B:$B,0)),"不适用/默认") | F10: =IFERROR(INDEX('06_核验映射过程'!$D:$D,MATCH(B10,'06_核验映射过程'!$B:$B,0)),"默认") | G10: =IFERROR(INDEX('07_权限映射过程'!$D:$D,MATCH(B10,'07_权限映射过程'!$B:$B,0)),"默认") | H10: =IF(D10="","待生成","已生成")
A11: 铝材模块 | B11: 铝材总嵌入排放(kgCO2e/申报单元) | C11: kgCO2e/declared unit | D11: =IFERROR(INDEX('10_CBAM中间表'!$D:$D,MATCH(B11,'10_CBAM中间表'!$B:$B,0)),"") | E11: =IFERROR(INDEX('05_证据映射过程'!$E:$E,MATCH(B11,'05_证据映射过程'!$B:$B,0)),"不适用/默认") | F11: =IFERROR(INDEX('06_核验映射过程'!$D:$D,MATCH(B11,'06_核验映射过程'!$B:$B,0)),"默认") | G11: =IFERROR(INDEX('07_权限映射过程'!$D:$D,MATCH(B11,'07_权限映射过程'!$B:$B,0)),"默认") | H11: =IF(D11="","待生成","已生成")
A12: 铝材模块 | B12: 铝材核验状态 | C12: 文本 | D12: =IFERROR(INDEX('10_CBAM中间表'!$D:$D,MATCH(B12,'10_CBAM中间表'!$B:$B,0)),"") | E12: =IFERROR(INDEX('05_证据映射过程'!$E:$E,MATCH(B12,'05_证据映射过程'!$B:$B,0)),"不适用/默认") | F12: =IFERROR(INDEX('06_核验映射过程'!$D:$D,MATCH(B12,'06_核验映射过程'!$B:$B,0)),"默认") | G12: =IFERROR(INDEX('07_权限映射过程'!$D:$D,MATCH(B12,'07_权限映射过程'!$B:$B,0)),"默认") | H12: =IF(D12="","待生成","已生成")
A13: 钢材模块 | B13: 钢材供应商安装点 ID | C13: 文本 | D13: =IFERROR(INDEX('10_CBAM中间表'!$D:$D,MATCH(B13,'10_CBAM中间表'!$B:$B,0)),"") | E13: =IFERROR(INDEX('05_证据映射过程'!$E:$E,MATCH(B13,'05_证据映射过程'!$B:$B,0)),"不适用/默认") | F13: =IFERROR(INDEX('06_核验映射过程'!$D:$D,MATCH(B13,'06_核验映射过程'!$B:$B,0)),"默认") | G13: =IFERROR(INDEX('07_权限映射过程'!$D:$D,MATCH(B13,'07_权限映射过程'!$B:$B,0)),"默认") | H13: =IF(D13="","待生成","已生成")
A14: 钢材模块 | B14: 钢材质量(kg) | C14: kg | D14: =IFERROR(INDEX('10_CBAM中间表'!$D:$D,MATCH(B14,'10_CBAM中间表'!$B:$B,0)),"") | E14: =IFERROR(INDEX('05_证据映射过程'!$E:$E,MATCH(B14,'05_证据映射过程'!$B:$B,0)),"不适用/默认") | F14: =IFERROR(INDEX('06_核验映射过程'!$D:$D,MATCH(B14,'06_核验映射过程'!$B:$B,0)),"默认") | G14: =IFERROR(INDEX('07_权限映射过程'!$D:$D,MATCH(B14,'07_权限映射过程'!$B:$B,0)),"默认") | H14: =IF(D14="","待生成","已生成")
A15: 钢材模块 | B15: 钢材直接排放因子(kgCO2e/kg) | C15: kgCO2e/kg | D15: =IFERROR(INDEX('10_CBAM中间表'!$D:$D,MATCH(B15,'10_CBAM中间表'!$B:$B,0)),"") | E15: =IFERROR(INDEX('05_证据映射过程'!$E:$E,MATCH(B15,'05_证据映射过程'!$B:$B,0)),"不适用/默认") | F15: =IFERROR(INDEX('06_核验映射过程'!$D:$D,MATCH(B15,'06_核验映射过程'!$B:$B,0)),"默认") | G15: =IFERROR(INDEX('07_权限映射过程'!$D:$D,MATCH(B15,'07_权限映射过程'!$B:$B,0)),"默认") | H15: =IF(D15="","待生成","已生成")
... A23: 综合状态 | B23: CBAM 兼容输出结论 | C23: 文本 | D23: =IFERROR(INDEX('10_CBAM中间表'!$D:$D,MATCH(B23,'10_CBAM中间表'!$B:$B,0)),"") | E23: =IFERROR(INDEX('05_证据映射过程'!$E:$E,MATCH(B23,'05_证据映射过程'!$B:$B,0)),"不适用/默认") | F23: =IFERROR(INDEX('06_核验映射过程'!$D:$D,MATCH(B23,'06_核验映射过程'!$B:$B,0)),"默认") | G23: =IFERROR(INDEX('07_权限映射过程'!$D:$D,MATCH(B23,'07_权限映射过程'!$B:$B,0)),"默认") | H23: =IF(D23="","待生成","已生成")

Sheet 04_字段映射过程
A1: 字段映射：从 CATL 输入到 EU / CBAM 输出
A3: 映射层 | B3: 目标字段 | C3: 输入字段代码 | D3: 输入当前值 | E3: 目标制度 | F3: 转换方式 | G3: 转换后结果预览 | H3: 是否关键
A4: 字段映射 | B4: 制造商名称 | C4: manufacturer_name | D4: =INDEX('01_手动输入'!$G:$G,MATCH("manufacturer_name",'01_手动输入'!$B:$B,0)) | E4: EU | F4: 直接映射 | G4: =INDEX('01_手动输入'!$G:$G,MATCH("manufacturer_name",'01_手动输入'!$B:$B,0)) | H4: 是
A5: 字段映射 | B5: 电池型号 | C5: model_code | D5: =INDEX('01_手动输入'!$G:$G,MATCH("model_code",'01_手动输入'!$B:$B,0)) | E5: EU+CBAM | F5: 直接映射 | G5: =INDEX('01_手动输入'!$G:$G,MATCH("model_code",'01_手动输入'!$B:$B,0)) | H5: 是
A6: 字段映射 | B6: 制造工厂代码 | C6: plant_code | D6: =INDEX('01_手动输入'!$G:$G,MATCH("plant_code",'01_手动输入'!$B:$B,0)) | E6: EU+CBAM | F6: 直接映射 | G6: =INDEX('01_手动输入'!$G:$G,MATCH("plant_code",'01_手动输入'!$B:$B,0)) | H6: 是
A7: 字段映射 | B7: 报告期 | C7: reporting_period | D7: =INDEX('01_手动输入'!$G:$G,MATCH("reporting_period",'01_手动输入'!$B:$B,0)) | E7: EU+CBAM | F7: 公司周期转产品周期 | G7: =INDEX('01_手动输入'!$G:$G,MATCH("reporting_period",'01_手动输入'!$B:$B,0)) | H7: 是
A8: 字段映射 | B8: 声明总碳足迹(kgCO2e/kWh) | C8: pack_capacity_kwh | D8: =INDEX('01_手动输入'!$G:$G,MATCH("pack_capacity_kwh",'01_手动输入'!$B:$B,0)) | E8: EU | F8: 生命周期计算后输出 | G8: 48.971631 | H8: 是
A9: 字段映射 | B9: 原材料阶段(kgCO2e/kWh) | C9: cathode_mass_kg | D9: 140 | E9: EU | F9: 材料质量 x 材料因子 | G9: 44.236111 | H9: 是
A10: 字段映射 | B10: 制造阶段(kgCO2e/kWh) | C10: grid_electricity_kwh | D10: 450 | E10: EU | F10: 能耗 + 工艺排放 + 良率调整 | G10: 4.3605201 | H10: 是
A11: 字段映射 | B11: 再生锂占比 | C11: recycled_lithium_pct | D11: 0.08 | E11: EU | F11: 直接映射 | G11: 0.08 | H11: 是
A12: 字段映射 | B12: 供应链追溯覆盖率 | C12: supplier_traceability_coverage_pct | D12: 0.92 | E12: EU | F12: 直接映射 | G12: 0.92 | H12: 是
A13: 字段映射 | B13: 铝材总嵌入排放(kgCO2e/申报单元) | C13: aluminium_mass_kg | D13: 80 | E13: CBAM | F13: 铝材质量 x (直接+间接因子) | G13: 1120 | H13: 是
A14: 字段映射 | B14: 钢材总嵌入排放(kgCO2e/申报单元) | C14: steel_mass_kg | D14: 30 | E14: CBAM | F14: 钢材质量 x (直接+间接因子) | G14: 81 | H14: 是
A15: 字段映射 | B15: 覆盖材料总嵌入排放(kgCO2e/申报单元) | C15: supplier_pcf_coverage_pct | D15: 0.76 | E15: CBAM | F15: 铝材 + 钢材汇总 | G15: 1201 | H15: 是
A16: 字段映射 | B16: 分层访问矩阵 | C16: access_matrix_status | D16: 齐备 | E16: EU+CBAM | F16: 控制结果可见范围 | G16: 齐备 | H16: 是

Sheet 05_证据映射过程
A1: 证据映射：每个输出字段背后需要什么证据
A3: 目标制度 | B3: 目标字段 | C3: 主要证据 | D3: 触发逻辑 | E3: 证据状态
A4: EU | B4: 制造商名称 | C4: 营业执照 / 年报 / 主体主数据 | D4: 有主体名称即通过 | E4: =IF(INDEX('01_手动输入'!$G:$G,MATCH("manufacturer_name",'01_手动输入'!$B:$B,0))<>"","证据齐备","待补证据")
A5: EU | B5: 产品名称 | C5: 产品主数据 / 型号注册表 | D5: 有产品名即通过 | E5: =IF(INDEX('01_手动输入'!$G:$G,MATCH("product_name",'01_手动输入'!$B:$B,0))<>"","证据齐备","待补证据")
A6: EU | B6: 电池型号 | C6: 型号注册表 / 产品主数据 | D6: 有型号即通过 | E6: =IF(INDEX('01_手动输入'!$G:$G,MATCH("model_code",'01_手动输入'!$B:$B,0))<>"","证据齐备","待补证据")
A7: EU | B7: 产品类别 | C7: 技术规格书 / 产品主数据 | D7: 有类别即通过 | E7: =IF(INDEX('01_手动输入'!$G:$G,MATCH("battery_category",'01_手动输入'!$B:$B,0))<>"","证据齐备","待补证据")
A8: EU | B8: 化学体系 | C8: 规格书 / BOM | D8: 有化学体系即通过 | E8: =IF(INDEX('01_手动输入'!$G:$G,MATCH("chemistry",'01_手动输入'!$B:$B,0))<>"","证据齐备","待补证据")
A9: EU | B9: 制造工厂代码 | C9: 工厂注册表 / 生产登记 | D9: 有工厂代码即通过 | E9: =IF(INDEX('01_手动输入'!$G:$G,MATCH("plant_code",'01_手动输入'!$B:$B,0))<>"","证据齐备","待补证据")
A10: EU | B10: 制造工厂名称 | C10: 工厂主数据 | D10: 有工厂名即通过 | E10: =IF(INDEX('01_手动输入'!$G:$G,MATCH("plant_name",'01_手动输入'!$B:$B,0))<>"","证据齐备","待补证据")
A11: EU | B11: 报告期 | C11: 产品报告期规则 / 排产记录 | D11: 有报告期即通过 | E11: =IF(INDEX('01_手动输入'!$G:$G,MATCH("reporting_period",'01_手动输入'!$B:$B,0))<>"","证据齐备","待补证据")
A12: EU | B12: 申报单元申报单元额定容量(kWh) | C12: 规格书 / 测试报告 | D12: 容量>0 | E12: =IF(AND(INDEX('01_手动输入'!$G:$G,MATCH("pack_capacity_kwh",'01_手动输入'!$B:$B,0))>0,INDEX('01_手动输入'!$G:$G,MATCH("test_report_status",'01_手动输入'!$B:$B,0))="齐备"),"证据齐备","待补证据")
A13: EU | B13: 标称电压(V) | C13: 规格书 / 测试报告 | D13: 电压>0 | E13: =IF(AND(INDEX('01_手动输入'!$G:$G,MATCH("nominal_voltage_v",'01_手动输入'!$B:$B,0))>0,INDEX('01_手动输入'!$G:$G,MATCH("test_report_status",'01_手动输入'!$B:$B,0))="齐备"),"证据齐备","待补证据")
A14: EU | B14: 循环寿命(cycles) | C14: 测试报告 | D14: 循环寿命>0 | E14: =IF(AND(INDEX('01_手动输入'!$G:$G,MATCH("cycle_life_cycles",'01_手动输入'!$B:$B,0))>0,INDEX('01_手动输入'!$G:$G,MATCH("test_report_status",'01_手动输入'!$B:$B,0))="齐备"),"证据齐备","待补证据")
A15: EU | B15: 声明总碳足迹(kgCO2e/申报单元) | C15: PCF 底稿 / BOM / 能耗 / 运输 / 回收数据 | D15: PCF 底稿齐备 | E15: =IF(INDEX('01_手动输入'!$G:$G,MATCH("pcf_study_status",'01_手动输入'!$B:$B,0))="齐备","证据齐备","待补证据")
A16: EU | B16: 声明总碳足迹(kgCO2e/kWh) | C16: PCF 底稿 / 容量数据 | D16: PCF 底稿齐备且容量>0 | E16: =IF(AND(INDEX('01_手动输入'!$G:$G,MATCH("pcf_study_status",'01_手动输入'!$B:$B,0))="齐备",INDEX('01_手动输入'!$G:$G,MATCH("pack_capacity_kwh",'01_手动输入'!$B:$B,0))>0),"证据齐备","待补证据")
A17: EU | B17: 原材料阶段(kgCO2e/kWh) | C17: BOM / 供应商PCF / 因子库 | D17: 材料量和因子齐备 | E17: =IF(AND(INDEX('01_手动输入'!$G:$G,MATCH("supplier_pcf_coverage_pct",'01_手动输入'!$B:$B,0))>=0.75,INDEX('01_手动输入'!$G:$G,MATCH("cathode_mass_kg",'01_手动输入'!$B:$B,0))>=0),"证据齐备","部分齐备")
A18: EU | B18: 制造阶段(kgCO2e/kWh) | C18: 电表 / 蒸汽 / 燃气 / 工艺排放记录 | D18: 工厂级能耗记录齐备 | E18: =IF(AND(INDEX('01_手动输入'!$G:$G,MATCH("grid_electricity_kwh",'01_手动输入'!$B:$B,0))>=0,INDEX('01_手动输入'!$G:$G,MATCH("steam_mj",'01_手动输入'!$B:$B,0))>=0,INDEX('01_手动输入'!$G:$G,MATCH("natural_gas_mj",'01_手动输入'!$B:$B,0))>=0),"证据齐备","待补证据")
A19: EU | B19: 运输阶段(kgCO2e/kWh) | C19: 物流记录 / 路线清单 | D19: 上下游运输数据齐备 | E19: =IF(AND(INDEX('01_手动输入'!$G:$G,MATCH("inbound_transport_kgco2",'01_手动输入'!$B:$B,0))<>"",INDEX('01_手动输入'!$G:$G,MATCH("outbound_transport_kgco2",'01_手动输入'!$B:$B,0))<>""),"证据齐备","待补证据")
A20: EU | B20: 终端回收阶段(kgCO2e/kWh) | C20: 回收方案 / 方法学说明 | D20: 回收信用值已声明 | E20: =IF(INDEX('01_手动输入'!$G:$G,MATCH("end_of_life_credit_kgco2",'01_手动输入'!$B:$B,0))<>"","证据齐备","待补证据")
A21: EU | B21: 再生锂占比 | C21: 质量平衡 / 供应商声明 | D21: 再生锂字段已填 | E21: =IF(INDEX('01_手动输入'!$G:$G,MATCH("recycled_lithium_pct",'01_手动输入'!$B:$B,0))>=0,"证据齐备","待补证据")
A22: EU | B22: 再生钴占比 | C22: 质量平衡 / 供应商声明 | D22: 即使为0也应有说明 | E22: =IF(INDEX('01_手动输入'!$G:$G,MATCH("recycled_cobalt_pct",'01_手动输入'!$B:$B,0))>=0,"证据齐备","待补证据")
A23: EU | B23: 再生镍占比 | C23: 质量平衡 / 供应商声明 | D23: 即使为0也应有说明 | E23: =IF(INDEX('01_手动输入'!$G:$G,MATCH("recycled_nickel_pct",'01_手动输入'!$B:$B,0))>=0,"证据齐备","待补证据")
A24: EU | B24: 再生铅占比 | C24: 质量平衡 / 供应商声明 | D24: 即使为0也应有说明 | E24: =IF(INDEX('01_手动输入'!$G:$G,MATCH("recycled_lead_pct",'01_手动输入'!$B:$B,0))>=0,"证据齐备","待补证据")
A25: EU | B25: 尽调政策链接 | C25: 官网政策 / 尽调制度文件 | D25: 有链接即可 | E25: =IF(INDEX('01_手动输入'!$G:$G,MATCH("due_diligence_policy_url",'01_手动输入'!$B:$B,0))<>"","证据齐备","待补证据")
A26: EU | B26: 关键原材料追溯范围 | C26: BOM / 追溯台账 | D26: 有追溯范围描述即可 | E26: =IF(INDEX('01_手动输入'!$G:$G,MATCH("critical_material_scope",'01_手动输入'!$B:$B,0))<>"","证据齐备","待补证据")
A27: EU | B27: 供应链追溯覆盖率 | C27: 追溯台账 / 供应商清单 | D27: 覆盖率>=0.9为强 | E27: =IF(INDEX('01_手动输入'!$G:$G,MATCH("supplier_traceability_coverage_pct",'01_手动输入'!$B:$B,0))>=0.9,"证据齐备",IF(INDEX('01_手动输入'!$G:$G,MATCH("supplier_traceability_coverage_pct",'01_手动输入'!$B:$B,0))>=0.7,"部分齐备","高风险"))
A28: EU | B28: 产品碳足迹研究底稿状态 | C28: PCF 研究底稿 | D28: 状态=齐备 | E28: =IF(INDEX('01_手动输入'!$G:$G,MATCH("pcf_study_status",'01_手动输入'!$B:$B,0))="齐备","证据齐备","待补证据")
A29: EU | B29: 测试报告状态 | C29: 测试报告原件 | D29: 状态=齐备 | E29: =IF(INDEX('01_手动输入'!$G:$G,MATCH("test_report_status",'01_手动输入'!$B:$B,0))="齐备","证据齐备","待补证据")
A30: EU | B30: 技术文档状态 | C30: 技术文档 / 说明书 / 计算书 | D30: 状态=齐备 | E30: =IF(INDEX('01_手动输入'!$G:$G,MATCH("technical_doc_status",'01_手动输入'!$B:$B,0))="齐备","证据齐备","待补证据")
A31: EU | B31: 护照对象 ID | C31: 护照系统对象主键 | D31: 对象ID不为空 | E31: =IF(INDEX('01_手动输入'!$G:$G,MATCH("qr_object_id",'01_手动输入'!$B:$B,0))<>"","证据齐备","待补证据")
A32: EU | B32: 个体电池编码前缀 | C32: 序列化规则 | D32: 前缀不为空 | E32: =IF(INDEX('01_手动输入'!$G:$G,MATCH("individual_battery_prefix",'01_手动输入'!$B:$B,0))<>"","证据齐备","待补证据")
A33: EU | B33: EU 输出完备度 | C33: 系统自动汇总 | D33: 完备度>=0.9 | E33: =IF('09_EU中间表'!D33>=0.9,"证据齐备","待补证据")
A34: EU | B34: EU 输出结论 | C34: 系统自动汇总 + 人工复核 | D34: 结论不为空 | E34: =IF('09_EU中间表'!D34<>"","证据齐备","待补证据")
A35: CBAM | B35: 电池型号 | C35: 产品主数据 | D35: 有型号即可 | E35: =IF(INDEX('01_手动输入'!$G:$G,MATCH("model_code",'01_手动输入'!$B:$B,0))<>"","证据齐备","待补证据")
A36: CBAM | B36: 产品报告期 | C36: 产品报告期规则 | D36: 有产品报告期即可 | E36: =IF(INDEX('01_手动输入'!$G:$G,MATCH("reporting_period",'01_手动输入'!$B:$B,0))<>"","证据齐备","待补证据")
A37: CBAM | B37: 上游材料报告期 | C37: 供应商报告期记录 | D37: 有上游报告期即可 | E37: =IF(INDEX('01_手动输入'!$G:$G,MATCH("upstream_reporting_period",'01_手动输入'!$B:$B,0))<>"","证据齐备","待补证据")
A38: CBAM | B38: 铝材供应商安装点 ID | C38: 安装点主数据 | D38: 有安装点ID即可 | E38: =IF(INDEX('01_手动输入'!$G:$G,MATCH("aluminium_supplier_installation_id",'01_手动输入'!$B:$B,0))<>"","证据齐备","待补证据")
A39: CBAM | B39: 铝材质量(kg) | C39: BOM / 结构件清单 | D39: 铝材质量>=0 | E39: =IF(INDEX('01_手动输入'!$G:$G,MATCH("aluminium_mass_kg",'01_手动输入'!$B:$B,0))>=0,"证据齐备","待补证据")
A40: CBAM | B40: 铝材直接排放因子(kgCO2e/kg) | C40: 供应商PCF / 安装点因子 | D40: 直接因子>=0 | E40: =IF(INDEX('01_手动输入'!$G:$G,MATCH("aluminium_direct_pcf",'01_手动输入'!$B:$B,0))>=0,"证据齐备","待补证据")
A41: CBAM | B41: 铝材间接排放因子(kgCO2e/kg) | C41: 供应商PCF / 电力因子 | D41: 间接因子>=0 | E41: =IF(INDEX('01_手动输入'!$G:$G,MATCH("aluminium_indirect_pcf",'01_手动输入'!$B:$B,0))>=0,"证据齐备","待补证据")
...

Sheet 06_核验映射过程
A1: 核验映射：谁来确认每一类数据
A3: 目标制度 | B3: 目标字段 | C3: 字段类型 | D3: 核验层级
A4: EU | B4: 制造商名称 | C4: 主体识别 | D4: 内部确认
A5: EU | B5: 产品名称 | C5: 产品主数据 | D5: 内部确认
A6: EU | B6: 电池型号 | C6: 产品主数据 | D6: 内部确认
A7: EU | B7: 产品类别 | C7: 产品分类 | D7: 内部确认
A8: EU | B8: 化学体系 | C8: 技术主数据 | D8: 内部确认
A9: EU | B9: 制造工厂代码 | C9: 工厂主数据 | D9: 内部确认
A10: EU | B10: 制造工厂名称 | C10: 工厂主数据 | D10: 内部确认
A11: EU | B11: 报告期 | C11: 报告锚点 | D11: 内部确认
A12: EU | B12: 申报单元申报单元额定容量(kWh) | C12: 性能参数 | D12: 测试+内部确认
A13: EU | B13: 标称电压(V) | C13: 性能参数 | D13: 测试+内部确认
A14: EU | B14: 循环寿命(cycles) | C14: 性能参数 | D14: 测试+内部确认
... A54: CBAM | B54: CBAM 兼容输出结论 | C54: 系统结论 | D54: 系统自动判定 + 管理层复核

Sheet 07_权限映射过程
A1: 权限映射：谁能看哪些数据
A3: 目标制度 | B3: 目标字段 | C3: 字段类型 | D3: 访问层级
A4: EU | B4: 制造商名称 | C4: 公开识别字段 | D4: 公开
A5: EU | B5: 产品名称 | C5: 公开展示字段 | D5: 公开
A6: EU | B6: 电池型号 | C6: 产品锚点 | D6: 受限
A7: EU | B7: 产品类别 | C7: 公开产品字段 | D7: 公开
A8: EU | B8: 化学体系 | C8: 公开产品字段 | D8: 公开
A9: EU | B9: 制造工厂代码 | C9: 工厂锚点 | D9: 受限
A10: EU | B10: 制造工厂名称 | C10: 工厂识别字段 | D10: 受限
A11: EU | B11: 报告期 | C11: 时间锚点 | D11: 受限
A12: EU | B12: 申报单元申报单元额定容量(kWh) | C12: 公开性能参数 | D12: 公开
A13: EU | B13: 标称电压(V) | C13: 公开性能参数 | D13: 公开
A14: EU | B14: 循环寿命(cycles) | C14: 公开性能参数 | D14: 公开
... A54: CBAM | B54: CBAM 兼容输出结论 | C54: 汇报摘要字段 | D54: 公开

Sheet 08_生命周期计算过程
A1: 生命周期碳足迹计算过程（全部自动公式）
A3: 计算模块 | B3: 计算项 | C3: 计算逻辑 | D3: 当前结果预览
A4: 原材料阶段 | B4: 正极材料排放 | C4: 质量 x 排放因子 | D4: 700
A5: 原材料阶段 | B5: 负极材料排放 | C5: 质量 x 排放因子 | D5: 455
A6: 原材料阶段 | B6: 电解液排放 | C6: 质量 x 排放因子 | D6: 280
A7: 原材料阶段 | B7: 隔膜排放 | C7: 质量 x 排放因子 | D7: 54
A8: 原材料阶段 | B8: 铜材排放 | C8: 质量 x 排放因子 | D8: 190
A9: 原材料阶段 | B9: 铝材直接排放 | C9: 质量 x 直接因子 | D9: 720
A10: 原材料阶段 | B10: 铝材间接排放 | C10: 质量 x 间接因子 | D10: 400
A11: 原材料阶段 | B11: 钢材直接排放 | C11: 质量 x 直接因子 | D11: 60
A12: 原材料阶段 | B12: 钢材间接排放 | C12: 质量 x 间接因子 | D12: 21
A13: 原材料阶段 | B13: 塑料件排放 | C13: 质量 x 排放因子 | D13: 75
A14: 原材料阶段 | B14: 其他材料排放 | C14: 质量 x 排放因子 | D14: 230
A15: 原材料阶段 | B15: 原材料阶段合计 | C15: 上述求和 | D15: 3185
... A33: CBAM影子 | B33: 覆盖材料占整包总排放比重 | C33: 覆盖材料总嵌入排放 / 整包总碳足迹 | D33: 0.3406167

Sheet 09_EU中间表
A1: 09_EU中间表
A3: 分组 | B3: 目标字段 | C3: 单位 | D3: 当前结果预览
A4: 基本信息 | B4: 制造商名称 | C4: 文本 | D4: =INDEX('01_手动输入'!$G:$G,MATCH("manufacturer_name",'01_手动输入'!$B:$B,0))
A5: 基本信息 | B5: 产品名称 | C5: 文本 | D5: =INDEX('01_手动输入'!$G:$G,MATCH("product_name",'01_手动输入'!$B:$B,0))
A6: 基本信息 | B6: 电池型号 | C6: 文本 | D6: =INDEX('01_手动输入'!$G:$G,MATCH("model_code",'01_手动输入'!$B:$B,0))
A7: 基本信息 | B7: 产品类别 | C7: 文本 | D7: =INDEX('01_手动输入'!$G:$G,MATCH("battery_category",'01_手动输入'!$B:$B,0))
A8: 基本信息 | B8: 化学体系 | C8: 文本 | D8: =INDEX('01_手动输入'!$G:$G,MATCH("chemistry",'01_手动输入'!$B:$B,0))
A9: 基本信息 | B9: 制造工厂代码 | C9: 文本 | D9: =INDEX('01_手动输入'!$G:$G,MATCH("plant_code",'01_手动输入'!$B:$B,0))
A10: 基本信息 | B10: 制造工厂名称 | C10: 文本 | D10: =INDEX('01_手动输入'!$G:$G,MATCH("plant_name",'01_手动输入'!$B:$B,0))
A11: 基本信息 | B11: 报告期 | C11: 文本 | D11: =INDEX('01_手动输入'!$G:$G,MATCH("reporting_period",'01_手动输入'!$B:$B,0))
A12: 产品参数 | B12: 申报单元申报单元额定容量(kWh) | C12: kWh | D12: 72
A13: 产品参数 | B13: 标称电压(V) | C13: V | D13: 800
A14: 产品参数 | B14: 循环寿命(cycles) | C14: cycles | D14: 4000
A15: 碳足迹 | B15: 声明总碳足迹(kgCO2e/申报单元) | C15: kgCO2e/declared unit | D15: 3525.9574
A16: 碳足迹 | B16: 声明总碳足迹(kgCO2e/kWh) | C16: kgCO2e/kWh | D16: 48.971631
A17: 碳足迹 | B17: 原材料阶段(kgCO2e/kWh) | C17: kgCO2e/kWh | D17: 44.236111
A18: 碳足迹 | B18: 制造阶段(kgCO2e/kWh) | C18: kgCO2e/kWh | D18: 4.3605201
A19: 碳足迹 | B19: 运输阶段(kgCO2e/kWh) | C19: kgCO2e/kWh | D19: 0.58333333
A20: 碳足迹 | B20: 终端回收阶段(kgCO2e/kWh) | C20: kgCO2e/kWh | D20: -0.20833333
A21: 再生材料 | B21: 再生锂占比 | C21: % | D21: 0.08
A22: 再生材料 | B22: 再生钴占比 | C22: % | D22: 0
A23: 再生材料 | B23: 再生镍占比 | C23: % | D23: 0
A24: 再生材料 | B24: 再生铅占比 | C24: % | D24: 0
A25: 尽调与追溯 | B25: 尽调政策链接 | C25: 文本 | D25: https://www.catl.com/
A26: 尽调与追溯 | B26: 关键原材料追溯范围 | C26: 文本 | D26: lithium / graphite / aluminium / copper / steel
A27: 尽调与追溯 | B27: 供应链追溯覆盖率 | C27: % | D27: 0.92
A28: 文件与护照 | B28: 产品碳足迹研究底稿状态 | C28: 文本 | D28: 齐备
A29: 文件与护照 | B29: 测试报告状态 | C29: 文本 | D29: 齐备
A30: 文件与护照 | B30: 技术文档状态 | C30: 文本 | D30: 齐备
A31: 文件与护照 | B31: 护照对象 ID | C31: 文本 | D31: passport-demo-001
A32: 文件与护照 | B32: 个体电池编码前缀 | C32: 文本 | D32: SXP25Q4
A33: 综合状态 | B33: EU 输出完备度 | C33: % | D33: 1
A34: 综合状态 | B34: EU 输出结论 | C34: 文本 | D34: 可作为通用模板示例输出

Sheet 10_CBAM中间表
A1: 10_CBAM中间表
A3: 分组 | B3: 目标字段 | C3: 单位 | D3: 当前结果预览
A4: 基础锚点 | B4: 电池型号 | C4: 文本 | D4: =INDEX('01_手动输入'!$G:$G,MATCH("model_code",'01_手动输入'!$B:$B,0))
A5: 基础锚点 | B5: 产品报告期 | C5: 文本 | D5: =INDEX('01_手动输入'!$G:$G,MATCH("reporting_period",'01_手动输入'!$B:$B,0))
A6: 基础锚点 | B6: 上游材料报告期 | C6: 文本 | D6: =INDEX('01_手动输入'!$G:$G,MATCH("upstream_reporting_period",'01_手动输入'!$B:$B,0))
A7: 铝材模块 | B7: 铝材供应商安装点 ID | C7: 文本 | D7: AL-SUP-001
A8: 铝材模块 | B8: 铝材质量(kg) | C8: kg | D8: 80
A9: 铝材模块 | B9: 铝材直接排放因子(kgCO2e/kg) | C9: kgCO2e/kg | D9: 9
A10: 铝材模块 | B10: 铝材间接排放因子(kgCO2e/kg) | C10: kgCO2e/kg | D10: 5
A11: 铝材模块 | B11: 铝材总嵌入排放(kgCO2e/申报单元) | C11: kgCO2e/declared unit | D11: 1120
A12: 铝材模块 | B12: 铝材核验状态 | C12: 文本 | D12: 已核验
A13: 钢材模块 | B13: 钢材供应商安装点 ID | C13: 文本 | D13: ST-SUP-001
A14: 钢材模块 | B14: 钢材质量(kg) | C14: kg | D14: 30
A15: 钢材模块 | B15: 钢材直接排放因子(kgCO2e/kg) | C15: kgCO2e/kg | D15: 2
A16: 钢材模块 | B16: 钢材间接排放因子(kgCO2e/kg) | C16: kgCO2e/kg | D16: 0.7
A17: 钢材模块 | B17: 钢材总嵌入排放(kgCO2e/申报单元) | C17: kgCO2e/declared unit | D17: 81
A18: 钢材模块 | B18: 钢材核验状态 | C18: 文本 | D18: 已核验
A19: 汇总 | B19: 覆盖材料总嵌入排放(kgCO2e/申报单元) | C19: kgCO2e/declared unit | D19: 1201
A20: 汇总 | B20: 覆盖材料占整包总排放比重 | C20: % | D20: 0.3406167
A21: 汇总 | B21: 供应商 PCF 覆盖率 | C21: % | D21: 0.76
A22: 综合状态 | B22: CBAM 兼容输出完备度 | C22: % | D22: 1
A23: 综合状态 | B23: CBAM 兼容输出结论 | C23: 文本 | D23: 可作为上游碳数据通用兼容模块示例

Sheet 11_CATL公开披露架构
A1: CATL 现有公开披露架构与拆分判断表
A2: 用途：把宁德时代现有公开披露资料拆成“哪些可以直接引用、哪些必须进一步拆分成 model/plant/supplier/material 级数据”。
A3: 主要来源 | B3: CATL 当前公开披露架构 | C3: 当前公开对象/粒度 | D3: 当前公开示例 | E3: 在我们系统中的角色 | F3: 可以直接引用什么 | G3: 必须拆分成什么明细数据 | H3: 更适合进入哪一层映射 | I3: 判断
A4: 2025 ESG 报告；2025 港股上市文件 | B4: 公司基本身份与业务范围 | C4: 公司/entity 级 | D4: 公司名称、主营业务、全球零碳新能源科技公司定位、业务范围 | E4: 作为系统最外层的公司身份锚点 | F4: 制造商名称、公司简介、业务范围、总部与联系方式 | G4: 电池型号代码、产品类别、化学体系、具体 demo 产品名 | H4: 字段映射 | I4: 公司级字段可直接引用，但不能替代产品主数据
